Workbook

Sheet 0% Grant, BVGEC recoup via Mixt
A2: Capacity Factor | B2: 0.17 | D2: Norfolk | E2: 0.33
A3: System Output | B3: 65000 | D3: BVGEC | E3: 0.33
A4: Hours per Year | B4: 8766 | D4: Community | E4: =1-E2-E3 -> 0.34
A5: System Size | B5: =$B$3/$B$4/$B$2 -> 43.617721
A6: Install Cost | B6: 2.5
A7: Capex | B7: =B5*B6*1000 -> 109044.3
A8: Degradation | B8: 0.005
A9: Inflation | B9: 0.03
A10: Admin Rate | B10: =$E$11 -> 0.0055 | D10: Combined OPEX Rate | E10: 0.0165
A11: Insurance Rate | B11: =$E$11 -> 0.0055 | D11: Individual | E11: =E10/3 -> 0.0055
A12: Maintenance Rate | B12: =$E$11 -> 0.0055
A13: CCA Rate | B13: 0.3
A14: Half Year Rule | B14: 0.5
A15: Grant Rate | B15: 0 | L15: Current Bill | M15: ='Bill Comparison'!F28 -> 322479.95
A16: Grant Amount | B16: =B7*B15 -> 0 | L16: New Bill | M16: ='Bill Comparison'!J28 -> 49771.697 | N16: Benefit Dist | O16: Annuity
A17: Net Capex | B17: =B7-B16 -> 109044.3 | L17: Available Savings | M17: ='Bill Comparison'!L28 -> 272708.26 | R17: Bill Saving | S17: =1-(I56+M16)/M15 -> -0.10394169
A18: Debt Rate | B18: 0.04 | L18: Norfolk Bill Savings | M18: =M17-I56 -> -33519.112 | N18: =M18/M19 -> -0.2948195
A19: Debt Term | B19: 10 | L19: Total Benefit | M19: =M18+T56+G56 -> 113693.67 | R19: Effective Savings | S19: =1-(M16+I56-M21)/M15 -> 0.012403253
L20: Norfolk Residual | M20: =M19*0.33-M18 -> 71038.024
L21: Norfolk Total | M21: =M18+M20 -> 37518.912 | N21: =M21/M19 -> 0.33 | O21: =M21/25 -> 1500.7565
A22: Repayment Start | B22: 3 | L22: BVGEC Residual | M22: =M19*0.45-G56 -> -14436.485
L23: BVGEC Total | M23: =M22+G56 -> 51162.153 | N23: =M23/M19 -> 0.45 | O23: =M23/25 -> 2046.4861
A24: Repayment Principal | B24: =B17/B19 -> 10904.43 | L24: Community | M24: =M19-M21-M23 -> 25012.608 | N24: =M24/M19 -> 0.22 | O24: =M24/25 -> 1000.5043
A25: Tax Rate | B25: 0.23 | N25: =N21+N23+N24 -> 1
A26: ITC Rate | B26: 0.3
A27: ITC Amount | B27: =B26*B17 -> 32713.291 | L27: Utilization | M27: =M19/M17 -> 0.41690587
A28: ITC year | B28: 1
H29: Effective PPA | I29: 0.2
A30: Year | B30: Effective Output | C30: Escalation Factor | D30: Admin Cost | E30: Insurance Cost | F30: Maintenance Cost | G30: OPEX | H30: Capital Cost Allowance | I30: Maxmimum Revenue | J30: Debt Principal | K30: Debt Interest | L30: ITC Credit | M30: Pre Tax Operating Cashflow | N30: Taxable Income Before Carry Forward Loss | O30: Carry Forward Losses | P30: Taxable Income After Carry Forward Loss | Q30: Tax | R30: After Tax Income | S30: Principal Repayent | T30: Cashflow To Equity
A31: 0 | B31: =POWER(1-$B$8,A31)*$B$3 -> 65000 | C31: =POWER(1+$B$9,A31) -> 1 | D31: =$B$7*C31*$B$10 -> 599.74366 | E31: =$B$7*$C31*$B$11 -> 599.74366 | F31: =$B$7*$C31*$B$12 -> 599.74366 | G31: =SUM(D31:F31) -> 1799.231 | H31: =IF(A31=0,$B$17*$B$14*$B$13,H30*$B$13) -> 16356.645 | I31: =$I$29*B31 -> 13000 | J31: =MAX(IF(A31>=$B$22,J30-$B$24,$B$17),0) -> 109044.3 | K31: =IF(A31>=$B$20,J31*$B$18,0) -> 4361.7721 | L31: =IF(A31=$B$28,$B$27,0) -> 0 | M31: =I31-G31-K31+L31 -> 6838.9969 | N31: =M31-H31 -> -9517.6484 | O31: =IF(N31<0,N31,0) -> -9517.6484 | P31: =N31-O31 -> 0 | Q31: =$B$25*P31 -> 0 | R31: =M31-Q31 -> 6838.9969 | S31: =IFERROR(__xludf.DUMMYFUNCTION("IF(ISBETWEEN(A31,$B$22,$B$22+$B$19-1),$B$24,0)"),0.0) -> 0 | T31: =R31-S31 -> 6838.9969 | U31: =T31 -> 6838.9969
A32: 1 | B32: =POWER(1-$B$8,A32)*$B$3 -> 64675 | C32: =POWER(1+$B$9,A32) -> 1.03 | D32: =$B$7*C32*$B$10 -> 617.73597 | E32: =$B$7*$C32*$B$11 -> 617.73597 | F32: =$B$7*$C32*$B$12 -> 617.73597 | G32: =SUM(D32:F32) -> 1853.2079 | H32: =IF(A32=0,$B$17*$B$14*$B$13,H31*$B$13) -> 4906.9936 | I32: =$I$29*B32 -> 12935 | J32: =MAX(IF(A32>=$B$22,J31-$B$24,$B$17),0) -> 109044.3 | K32: =IF(A32>=$B$20,J32*$B$18,0) -> 4361.7721 | L32: =IF(A32=$B$28,$B$27,0) -> 32713.291 | M32: =I32-G32-K32+L32 -> 39433.311 | N32: =M32-H32 -> 34526.317 | O32: =IF(N32<0,N32,0) -> 0 | P32: =IF(N32>0,N32+O31,0) -> 25008.669 | Q32: =$B$25*P32 -> 5751.9938 | R32: =M32-Q32 -> 33681.317 | S32: =IFERROR(__xludf.DUMMYFUNCTION("IF(ISBETWEEN(A32,$B$22,$B$22+$B$19-1),$B$24,0)"),0.0) -> 0 | T32: =R32-S32 -> 33681.317 | U32: =T32+U31 -> 40520.314
A33: 2 | B33: =POWER(1-$B$8,A33)*$B$3 -> 64351.625 | C33: =POWER(1+$B$9,A33) -> 1.0609 | D33: =$B$7*C33*$B$10 -> 636.26805 | E33: =$B$7*$C33*$B$11 -> 636.26805 | F33: =$B$7*$C33*$B$12 -> 636.26805 | G33: =SUM(D33:F33) -> 1908.8042 | H33: =IF(A33=0,$B$17*$B$14*$B$13,H32*$B$13) -> 1472.0981 | I33: =$I$29*B33 -> 12870.325 | J33: =MAX(IF(A33>=$B$22,J32-$B$24,$B$17),0) -> 109044.3 | K33: =IF(A33>=$B$20,J33*$B$18,0) -> 4361.7721 | L33: =IF(A33=$B$28,$B$27,0) -> 0 | M33: =I33-G33-K33+L33 -> 6599.7488 | N33: =M33-H33 -> 5127.6507 | O33: =IF(N33<0,N33,0) -> 0 | P33: =IF(N33>0,N33+O32,0) -> 5127.6507 | Q33: =$B$25*P33 -> 1179.3597 | R33: =M33-Q33 -> 5420.3891 | S33: =IFERROR(__xludf.DUMMYFUNCTION("IF(ISBETWEEN(A33,$B$22,$B$22+$B$19-1),$B$24,0)"),0.0) -> 0 | T33: =R33-S33 -> 5420.3891 | U33: =T33+U32 -> 45940.703
A34: 3 | B34: =POWER(1-$B$8,A34)*$B$3 -> 64029.867 | C34: =POWER(1+$B$9,A34) -> 1.092727 | D34: =$B$7*C34*$B$10 -> 655.35609 | E34: =$B$7*$C34*$B$11 -> 655.35609 | F34: =$B$7*$C34*$B$12 -> 655.35609 | G34: =SUM(D34:F34) -> 1966.0683 | H34: =IF(A34=0,$B$17*$B$14*$B$13,H33*$B$13) -> 441.62942 | I34: =$I$29*B34 -> 12805.973 | J34: =MAX(IF(A34>=$B$22,J33-$B$24,$B$17),0) -> 98139.872 | K34: =IF(A34>=$B$20,J34*$B$18,0) -> 3925.5949 | L34: =IF(A34=$B$28,$B$27,0) -> 0 | M34: =I34-G34-K34+L34 -> 6914.3102 | N34: =M34-H34 -> 6472.6808 | O34: =IF(N34<0,N34,0) -> 0 | P34: =IF(N34>0,N34+O33,0) -> 6472.6808 | Q34: =$B$25*P34 -> 1488.7166 | R34: =M34-Q34 -> 5425.5936 | S34: =IFERROR(__xludf.DUMMYFUNCTION("IF(ISBETWEEN(A34,$B$22,$B$22+$B$19-1),$B$24,0)"),10904.430218357022) -> 10904.43 | T34: =R34-S34 -> -5478.8366 | U34: =T34+U33 -> 40461.866
A35: 4 | B35: =POWER(1-$B$8,A35)*$B$3 -> 63709.718 | C35: =POWER(1+$B$9,A35) -> 1.1255088 | D35: =$B$7*C35*$B$10 -> 675.01678 | E35: =$B$7*$C35*$B$11 -> 675.01678 | F35: =$B$7*$C35*$B$12 -> 675.01678 | G35: =SUM(D35:F35) -> 2025.0503 | H35: =IF(A35=0,$B$17*$B$14*$B$13,H34*$B$13) -> 132.48883 | I35: =$I$29*B35 -> 12741.944 | J35: =MAX(IF(A35>=$B$22,J34-$B$24,$B$17),0) -> 87235.442 | K35: =IF(A35>=$B$20,J35*$B$18,0) -> 3489.4177 | L35: =IF(A35=$B$28,$B$27,0) -> 0 | M35: =I35-G35-K35+L35 -> 7227.4755 | N35: =M35-H35 -> 7094.9867 | O35: =IF(N35<0,N35,0) -> 0 | P35: =IF(N35>0,N35+O34,0) -> 7094.9867 | Q35: =$B$25*P35 -> 1631.8469 | R35: =M35-Q35 -> 5595.6286 | S35: =IFERROR(__xludf.DUMMYFUNCTION("IF(ISBETWEEN(A35,$B$22,$B$22+$B$19-1),$B$24,0)"),10904.430218357022) -> 10904.43 | T35: =R35-S35 -> -5308.8016 | U35: =T35+U34 -> 35153.065
A36: 5 | B36: =POWER(1-$B$8,A36)*$B$3 -> 63391.169 | C36: =POWER(1+$B$9,A36) -> 1.1592741 | D36: =$B$7*C36*$B$10 -> 695.26728 | E36: =$B$7*$C36*$B$11 -> 695.26728 | F36: =$B$7*$C36*$B$12 -> 695.26728 | G36: =SUM(D36:F36) -> 2085.8018 | H36: =IF(A36=0,$B$17*$B$14*$B$13,H35*$B$13) -> 39.746648 | I36: =$I$29*B36 -> 12678.234 | J36: =MAX(IF(A36>=$B$22,J35-$B$24,$B$17),0) -> 76331.012 | K36: =IF(A36>=$B$20,J36*$B$18,0) -> 3053.2405 | L36: =IF(A36=$B$28,$B$27,0) -> 0 | M36: =I36-G36-K36+L36 -> 7539.1915 | N36: =M36-H36 -> 7499.4448 | O36: =IF(N36<0,N36,0) -> 0 | P36: =IF(N36>0,N36+O35,0) -> 7499.4448 | Q36: =$B$25*P36 -> 1724.8723 | R36: =M36-Q36 -> 5814.3192 | S36: =IFERROR(__xludf.DUMMYFUNCTION("IF(ISBETWEEN(A36,$B$22,$B$22+$B$19-1),$B$24,0)"),10904.430218357022) -> 10904.43 | T36: =R36-S36 -> -5090.111 | U36: =T36+U35 -> 30062.954
A37: 6 | B37: =POWER(1-$B$8,A37)*$B$3 -> 63074.213 | C37: =POWER(1+$B$9,A37) -> 1.1940523 | D37: =$B$7*C37*$B$10 -> 716.1253 | E37: =$B$7*$C37*$B$11 -> 716.1253 | F37: =$B$7*$C37*$B$12 -> 716.1253 | G37: =SUM(D37:F37) -> 2148.3759 | H37: =IF(A37=0,$B$17*$B$14*$B$13,H36*$B$13) -> 11.923994 | I37: =$I$29*B37 -> 12614.843 | J37: =MAX(IF(A37>=$B$22,J36-$B$24,$B$17),0) -> 65426.581 | K37: =IF(A37>=$B$20,J37*$B$18,0) -> 2617.0633 | L37: =IF(A37=$B$28,$B$27,0) -> 0 | M37: =I37-G37-K37+L37 -> 7849.4035 | N37: =M37-H37 -> 7837.4795 | O37: =IF(N37<0,N37,0) -> 0 | P37: =IF(N37>0,N37+O36,0) -> 7837.4795 | Q37: =$B$25*P37 -> 1802.6203 | R37: =M37-Q37 -> 6046.7832 | S37: =IFERROR(__xludf.DUMMYFUNCTION("IF(ISBETWEEN(A37,$B$22,$B$22+$B$19-1),$B$24,0)"),10904.430218357022) -> 10904.43 | T37: =R37-S37 -> -4857.647 | U37: =T37+U36 -> 25205.307
A38: 7 | B38: =POWER(1-$B$8,A38)*$B$3 -> 62758.842 | C38: =POWER(1+$B$9,A38) -> 1.2298739 | D38: =$B$7*C38*$B$10 -> 737.60906 | E38: =$B$7*$C38*$B$11 -> 737.60906 | F38: =$B$7*$C38*$B$12 -> 737.60906 | G38: =SUM(D38:F38) -> 2212.8272 | H38: =IF(A38=0,$B$17*$B$14*$B$13,H37*$B$13) -> 3.5771983 | I38: =$I$29*B38 -> 12551.768 | J38: =MAX(IF(A38>=$B$22,J37-$B$24,$B$17),0) -> 54522.151 | K38: =IF(A38>=$B$20,J38*$B$18,0) -> 2180.886 | L38: =IF(A38=$B$28,$B$27,0) -> 0 | M38: =I38-G38-K38+L38 -> 8158.0552 | N38: =M38-H38 -> 8154.478 | O38: =IF(N38<0,N38,0) -> 0 | P38: =IF(N38>0,N38+O37,0) -> 8154.478 | Q38: =$B$25*P38 -> 1875.5299 | R38: =M38-Q38 -> 6282.5253 | S38: =IFERROR(__xludf.DUMMYFUNCTION("IF(ISBETWEEN(A38,$B$22,$B$22+$B$19-1),$B$24,0)"),10904.430218357022) -> 10904.43 | T38: =R38-S38 -> -4621.905 | U38: =T38+U37 -> 20583.402
A39: 8 | B39: =POWER(1-$B$8,A39)*$B$3 -> 62445.048 | C39: =POWER(1+$B$9,A39) -> 1.2667701 | D39: =$B$7*C39*$B$10 -> 759.73733 | E39: =$B$7*$C39*$B$11 -> 759.73733 | F39: =$B$7*$C39*$B$12 -> 759.73733 | G39: =SUM(D39:F39) -> 2279.212 | H39: =IF(A39=0,$B$17*$B$14*$B$13,H38*$B$13) -> 1.0731595 | I39: =$I$29*B39 -> 12489.01 | J39: =MAX(IF(A39>=$B$22,J38-$B$24,$B$17),0) -> 43617.721 | K39: =IF(A39>=$B$20,J39*$B$18,0) -> 1744.7088 | L39: =IF(A39=$B$28,$B$27,0) -> 0 | M39: =I39-G39-K39+L39 -> 8465.0887 | N39: =M39-H39 -> 8464.0156 | O39: =IF(N39<0,N39,0) -> 0 | P39: =IF(N39>0,N39+O38,0) -> 8464.0156 | Q39: =$B$25*P39 -> 1946.7236 | R39: =M39-Q39 -> 6518.3652 | S39: =IFERROR(__xludf.DUMMYFUNCTION("IF(ISBETWEEN(A39,$B$22,$B$22+$B$19-1),$B$24,0)"),10904.430218357022) -> 10904.43 | T39: =R39-S39 -> -4386.0651 | U39: =T39+U38 -> 16197.337
A40: 9 | B40: =POWER(1-$B$8,A40)*$B$3 -> 62132.823 | C40: =POWER(1+$B$9,A40) -> 1.3047732 | D40: =$B$7*C40*$B$10 -> 782.52945 | E40: =$B$7*$C40*$B$11 -> 782.52945 | F40: =$B$7*$C40*$B$12 -> 782.52945 | G40: =SUM(D40:F40) -> 2347.5883 | H40: =IF(A40=0,$B$17*$B$14*$B$13,H39*$B$13) -> 0.32194785 | I40: =$I$29*B40 -> 12426.565 | J40: =MAX(IF(A40>=$B$22,J39-$B$24,$B$17),0) -> 32713.291 | K40: =IF(A40>=$B$20,J40*$B$18,0) -> 1308.5316 | L40: =IF(A40=$B$28,$B$27,0) -> 0 | M40: =I40-G40-K40+L40 -> 8770.4446 | N40: =M40-H40 -> 8770.1226 | O40: =IF(N40<0,N40,0) -> 0 | P40: =IF(N40>0,N40+O39,0) -> 8770.1226 | Q40: =$B$25*P40 -> 2017.1282 | R40: =M40-Q40 -> 6753.3164 | S40: =IFERROR(__xludf.DUMMYFUNCTION("IF(ISBETWEEN(A40,$B$22,$B$22+$B$19-1),$B$24,0)"),10904.430218357022) -> 10904.43 | T40: =R40-S40 -> -4151.1139 | U40: =T40+U39 -> 12046.223
A41: 10 | B41: =POWER(1-$B$8,A41)*$B$3 -> 61822.158 | C41: =POWER(1+$B$9,A41) -> 1.3439164 | D41: =$B$7*C41*$B$10 -> 806.00533 | E41: =$B$7*$C41*$B$11 -> 806.00533 | F41: =$B$7*$C41*$B$12 -> 806.00533 | G41: =SUM(D41:F41) -> 2418.016 | H41: =IF(A41=0,$B$17*$B$14*$B$13,H40*$B$13) -> 0.096584355 | I41: =$I$29*B41 -> 12364.432 | J41: =MAX(IF(A41>=$B$22,J40-$B$24,$B$17),0) -> 21808.86 | K41: =IF(A41>=$B$20,J41*$B$18,0) -> 872.35442 | L41: =IF(A41=$B$28,$B$27,0) -> 0 | M41: =I41-G41-K41+L41 -> 9074.0613 | N41: =M41-H41 -> 9073.9647 | O41: =IF(N41<0,N41,0) -> 0 | P41: =IF(N41>0,N41+O40,0) -> 9073.9647 | Q41: =$B$25*P41 -> 2087.0119 | R41: =M41-Q41 -> 6987.0494 | S41: =IFERROR(__xludf.DUMMYFUNCTION("IF(ISBETWEEN(A41,$B$22,$B$22+$B$19-1),$B$24,0)"),10904.430218357022) -> 10904.43 | T41: =R41-S41 -> -3917.3808 | U41: =T41+U40 -> 8128.8419
...

Sheet 0% Grant, BVGEC recoup via Prof
A2: Capacity Factor | B2: 0.17 | D2: Norfolk | E2: 0.33
A3: System Output | B3: 65000 | D3: BVGEC | E3: 0.33
A4: Hours per Year | B4: 8766 | D4: Community | E4: =1-E2-E3 -> 0.34
A5: System Size | B5: =$B$3/$B$4/$B$2 -> 43.617721
A6: Install Cost | B6: 2.5
A7: Capex | B7: =B5*B6*1000 -> 109044.3
A8: Degradation | B8: 0.005
A9: Inflation | B9: 0.03
A10: Admin Rate | B10: =$E$11 -> 0 | D10: Combined OPEX Rate | E10: 0
A11: Insurance Rate | B11: =$E$11 -> 0 | D11: Individual | E11: =E10/3 -> 0
A12: Maintenance Rate | B12: =$E$11 -> 0
A13: CCA Rate | B13: 0.3
A14: Half Year Rule | B14: 0.5
A15: Grant Rate | B15: 0 | L15: Current Bill | M15: ='Bill Comparison'!F28 -> 322479.95
A16: Grant Amount | B16: =B7*B15 -> 0 | L16: New Bill | M16: ='Bill Comparison'!J28 -> 49771.697 | N16: Benefit Dist | O16: Annuity
A17: Net Capex | B17: =B7-B16 -> 109044.3 | L17: Available Savings | M17: ='Bill Comparison'!L28 -> 272708.26 | R17: Bill Saving | S17: =1-(I56+M16)/M15 -> 0.062238529
A18: Debt Rate | B18: 0.04 | L18: Norfolk Bill Savings | M18: =M17-I56 -> 20070.678 | N18: =M18/M19 -> 0.18092835
A19: Debt Term | B19: 10 | L19: Total Benefit | M19: =M18+T56+G56 -> 110931.64 | R19: Effective Savings | S19: =1-(M16+I56-M21)/M15 -> 0.17575703
L20: Norfolk Residual | M20: =M19*0.33-M18 -> 16536.763
L21: Norfolk Total | M21: =M18+M20 -> 36607.44 | N21: =M21/M19 -> 0.33 | O21: =M21/25 -> 1464.2976
A22: Repayment Start | B22: 3 | L22: BVGEC Residual | M22: =M19*0.45-G56 -> 49919.237
L23: BVGEC Total | M23: =M22+G56 -> 49919.237 | N23: =M23/M19 -> 0.45 | O23: =M23/25 -> 1996.7695
A24: Repayment Principal | B24: =B17/B19 -> 10904.43 | L24: Community | M24: =M19-M21-M23 -> 24404.96 | N24: =M24/M19 -> 0.22 | O24: =M24/25 -> 976.19841
A25: Tax Rate | B25: 0.23 | N25: =N21+N23+N24 -> 1
A26: ITC Rate | B26: 0.3
A27: ITC Amount | B27: =B26*B17 -> 32713.291 | L27: Utilization | M27: =M19/M17 -> 0.4067777
A28: ITC year | B28: 1
H29: Effective PPA | I29: 0.165
A30: Year | B30: Effective Output | C30: Escalation Factor | D30: Admin Cost | E30: Insurance Cost | F30: Maintenance Cost | G30: OPEX | H30: Capital Cost Allowance | I30: Maxmimum Revenue | J30: Debt Principal | K30: Debt Interest | L30: ITC Credit | M30: Pre Tax Operating Cashflow | N30: Taxable Income Before Carry Forward Loss | O30: Carry Forward Losses | P30: Taxable Income After Carry Forward Loss | Q30: Tax | R30: After Tax Income | S30: Principal Repayent | T30: Cashflow To Equity
A31: 0 | B31: =POWER(1-$B$8,A31)*$B$3 -> 65000 | C31: =POWER(1+$B$9,A31) -> 1 | D31: =$B$7*C31*$B$10 -> 0 | E31: =$B$7*$C31*$B$11 -> 0 | F31: =$B$7*$C31*$B$12 -> 0 | G31: =SUM(D31:F31) -> 0 | H31: =IF(A31=0,$B$17*$B$14*$B$13,H30*$B$13) -> 16356.645 | I31: =$I$29*B31 -> 10725 | J31: =MAX(IF(A31>=$B$22,J30-$B$24,$B$17),0) -> 109044.3 | K31: =IF(A31>=$B$20,J31*$B$18,0) -> 4361.7721 | L31: =IF(A31=$B$28,$B$27,0) -> 0 | M31: =I31-G31-K31+L31 -> 6363.2279 | N31: =M31-H31 -> -9993.4174 | O31: =IF(N31<0,N31,0) -> -9993.4174 | P31: =N31-O31 -> 0 | Q31: =$B$25*P31 -> 0 | R31: =M31-Q31 -> 6363.2279 | S31: =IFERROR(__xludf.DUMMYFUNCTION("IF(ISBETWEEN(A31,$B$22,$B$22+$B$19-1),$B$24,0)"),0.0) -> 0 | T31: =R31-S31 -> 6363.2279 | U31: =T31 -> 6363.2279
A32: 1 | B32: =POWER(1-$B$8,A32)*$B$3 -> 64675 | C32: =POWER(1+$B$9,A32) -> 1.03 | D32: =$B$7*C32*$B$10 -> 0 | E32: =$B$7*$C32*$B$11 -> 0 | F32: =$B$7*$C32*$B$12 -> 0 | G32: =SUM(D32:F32) -> 0 | H32: =IF(A32=0,$B$17*$B$14*$B$13,H31*$B$13) -> 4906.9936 | I32: =$I$29*B32 -> 10671.375 | J32: =MAX(IF(A32>=$B$22,J31-$B$24,$B$17),0) -> 109044.3 | K32: =IF(A32>=$B$20,J32*$B$18,0) -> 4361.7721 | L32: =IF(A32=$B$28,$B$27,0) -> 32713.291 | M32: =I32-G32-K32+L32 -> 39022.894 | N32: =M32-H32 -> 34115.9 | O32: =IF(N32<0,N32,0) -> 0 | P32: =IF(N32>0,N32+O31,0) -> 24122.483 | Q32: =$B$25*P32 -> 5548.171 | R32: =M32-Q32 -> 33474.723 | S32: =IFERROR(__xludf.DUMMYFUNCTION("IF(ISBETWEEN(A32,$B$22,$B$22+$B$19-1),$B$24,0)"),0.0) -> 0 | T32: =R32-S32 -> 33474.723 | U32: =T32+U31 -> 39837.95
A33: 2 | B33: =POWER(1-$B$8,A33)*$B$3 -> 64351.625 | C33: =POWER(1+$B$9,A33) -> 1.0609 | D33: =$B$7*C33*$B$10 -> 0 | E33: =$B$7*$C33*$B$11 -> 0 | F33: =$B$7*$C33*$B$12 -> 0 | G33: =SUM(D33:F33) -> 0 | H33: =IF(A33=0,$B$17*$B$14*$B$13,H32*$B$13) -> 1472.0981 | I33: =$I$29*B33 -> 10618.018 | J33: =MAX(IF(A33>=$B$22,J32-$B$24,$B$17),0) -> 109044.3 | K33: =IF(A33>=$B$20,J33*$B$18,0) -> 4361.7721 | L33: =IF(A33=$B$28,$B$27,0) -> 0 | M33: =I33-G33-K33+L33 -> 6256.246 | N33: =M33-H33 -> 4784.148 | O33: =IF(N33<0,N33,0) -> 0 | P33: =IF(N33>0,N33+O32,0) -> 4784.148 | Q33: =$B$25*P33 -> 1100.354 | R33: =M33-Q33 -> 5155.892 | S33: =IFERROR(__xludf.DUMMYFUNCTION("IF(ISBETWEEN(A33,$B$22,$B$22+$B$19-1),$B$24,0)"),0.0) -> 0 | T33: =R33-S33 -> 5155.892 | U33: =T33+U32 -> 44993.842
A34: 3 | B34: =POWER(1-$B$8,A34)*$B$3 -> 64029.867 | C34: =POWER(1+$B$9,A34) -> 1.092727 | D34: =$B$7*C34*$B$10 -> 0 | E34: =$B$7*$C34*$B$11 -> 0 | F34: =$B$7*$C34*$B$12 -> 0 | G34: =SUM(D34:F34) -> 0 | H34: =IF(A34=0,$B$17*$B$14*$B$13,H33*$B$13) -> 441.62942 | I34: =$I$29*B34 -> 10564.928 | J34: =MAX(IF(A34>=$B$22,J33-$B$24,$B$17),0) -> 98139.872 | K34: =IF(A34>=$B$20,J34*$B$18,0) -> 3925.5949 | L34: =IF(A34=$B$28,$B$27,0) -> 0 | M34: =I34-G34-K34+L34 -> 6639.3332 | N34: =M34-H34 -> 6197.7037 | O34: =IF(N34<0,N34,0) -> 0 | P34: =IF(N34>0,N34+O33,0) -> 6197.7037 | Q34: =$B$25*P34 -> 1425.4719 | R34: =M34-Q34 -> 5213.8613 | S34: =IFERROR(__xludf.DUMMYFUNCTION("IF(ISBETWEEN(A34,$B$22,$B$22+$B$19-1),$B$24,0)"),10904.430218357022) -> 10904.43 | T34: =R34-S34 -> -5690.5689 | U34: =T34+U33 -> 39303.274
A35: 4 | B35: =POWER(1-$B$8,A35)*$B$3 -> 63709.718 | C35: =POWER(1+$B$9,A35) -> 1.1255088 | D35: =$B$7*C35*$B$10 -> 0 | E35: =$B$7*$C35*$B$11 -> 0 | F35: =$B$7*$C35*$B$12 -> 0 | G35: =SUM(D35:F35) -> 0 | H35: =IF(A35=0,$B$17*$B$14*$B$13,H34*$B$13) -> 132.48883 | I35: =$I$29*B35 -> 10512.103 | J35: =MAX(IF(A35>=$B$22,J34-$B$24,$B$17),0) -> 87235.442 | K35: =IF(A35>=$B$20,J35*$B$18,0) -> 3489.4177 | L35: =IF(A35=$B$28,$B$27,0) -> 0 | M35: =I35-G35-K35+L35 -> 7022.6857 | N35: =M35-H35 -> 6890.1969 | O35: =IF(N35<0,N35,0) -> 0 | P35: =IF(N35>0,N35+O34,0) -> 6890.1969 | Q35: =$B$25*P35 -> 1584.7453 | R35: =M35-Q35 -> 5437.9404 | S35: =IFERROR(__xludf.DUMMYFUNCTION("IF(ISBETWEEN(A35,$B$22,$B$22+$B$19-1),$B$24,0)"),10904.430218357022) -> 10904.43 | T35: =R35-S35 -> -5466.4898 | U35: =T35+U34 -> 33836.784
A36: 5 | B36: =POWER(1-$B$8,A36)*$B$3 -> 63391.169 | C36: =POWER(1+$B$9,A36) -> 1.1592741 | D36: =$B$7*C36*$B$10 -> 0 | E36: =$B$7*$C36*$B$11 -> 0 | F36: =$B$7*$C36*$B$12 -> 0 | G36: =SUM(D36:F36) -> 0 | H36: =IF(A36=0,$B$17*$B$14*$B$13,H35*$B$13) -> 39.746648 | I36: =$I$29*B36 -> 10459.543 | J36: =MAX(IF(A36>=$B$22,J35-$B$24,$B$17),0) -> 76331.012 | K36: =IF(A36>=$B$20,J36*$B$18,0) -> 3053.2405 | L36: =IF(A36=$B$28,$B$27,0) -> 0 | M36: =I36-G36-K36+L36 -> 7406.3024 | N36: =M36-H36 -> 7366.5558 | O36: =IF(N36<0,N36,0) -> 0 | P36: =IF(N36>0,N36+O35,0) -> 7366.5558 | Q36: =$B$25*P36 -> 1694.3078 | R36: =M36-Q36 -> 5711.9946 | S36: =IFERROR(__xludf.DUMMYFUNCTION("IF(ISBETWEEN(A36,$B$22,$B$22+$B$19-1),$B$24,0)"),10904.430218357022) -> 10904.43 | T36: =R36-S36 -> -5192.4356 | U36: =T36+U35 -> 28644.348
A37: 6 | B37: =POWER(1-$B$8,A37)*$B$3 -> 63074.213 | C37: =POWER(1+$B$9,A37) -> 1.1940523 | D37: =$B$7*C37*$B$10 -> 0 | E37: =$B$7*$C37*$B$11 -> 0 | F37: =$B$7*$C37*$B$12 -> 0 | G37: =SUM(D37:F37) -> 0 | H37: =IF(A37=0,$B$17*$B$14*$B$13,H36*$B$13) -> 11.923994 | I37: =$I$29*B37 -> 10407.245 | J37: =MAX(IF(A37>=$B$22,J36-$B$24,$B$17),0) -> 65426.581 | K37: =IF(A37>=$B$20,J37*$B$18,0) -> 2617.0633 | L37: =IF(A37=$B$28,$B$27,0) -> 0 | M37: =I37-G37-K37+L37 -> 7790.1819 | N37: =M37-H37 -> 7778.2579 | O37: =IF(N37<0,N37,0) -> 0 | P37: =IF(N37>0,N37+O36,0) -> 7778.2579 | Q37: =$B$25*P37 -> 1788.9993 | R37: =M37-Q37 -> 6001.1826 | S37: =IFERROR(__xludf.DUMMYFUNCTION("IF(ISBETWEEN(A37,$B$22,$B$22+$B$19-1),$B$24,0)"),10904.430218357022) -> 10904.43 | T37: =R37-S37 -> -4903.2476 | U37: =T37+U36 -> 23741.101
A38: 7 | B38: =POWER(1-$B$8,A38)*$B$3 -> 62758.842 | C38: =POWER(1+$B$9,A38) -> 1.2298739 | D38: =$B$7*C38*$B$10 -> 0 | E38: =$B$7*$C38*$B$11 -> 0 | F38: =$B$7*$C38*$B$12 -> 0 | G38: =SUM(D38:F38) -> 0 | H38: =IF(A38=0,$B$17*$B$14*$B$13,H37*$B$13) -> 3.5771983 | I38: =$I$29*B38 -> 10355.209 | J38: =MAX(IF(A38>=$B$22,J37-$B$24,$B$17),0) -> 54522.151 | K38: =IF(A38>=$B$20,J38*$B$18,0) -> 2180.886 | L38: =IF(A38=$B$28,$B$27,0) -> 0 | M38: =I38-G38-K38+L38 -> 8174.3229 | N38: =M38-H38 -> 8170.7457 | O38: =IF(N38<0,N38,0) -> 0 | P38: =IF(N38>0,N38+O37,0) -> 8170.7457 | Q38: =$B$25*P38 -> 1879.2715 | R38: =M38-Q38 -> 6295.0514 | S38: =IFERROR(__xludf.DUMMYFUNCTION("IF(ISBETWEEN(A38,$B$22,$B$22+$B$19-1),$B$24,0)"),10904.430218357022) -> 10904.43 | T38: =R38-S38 -> -4609.3788 | U38: =T38+U37 -> 19131.722
A39: 8 | B39: =POWER(1-$B$8,A39)*$B$3 -> 62445.048 | C39: =POWER(1+$B$9,A39) -> 1.2667701 | D39: =$B$7*C39*$B$10 -> 0 | E39: =$B$7*$C39*$B$11 -> 0 | F39: =$B$7*$C39*$B$12 -> 0 | G39: =SUM(D39:F39) -> 0 | H39: =IF(A39=0,$B$17*$B$14*$B$13,H38*$B$13) -> 1.0731595 | I39: =$I$29*B39 -> 10303.433 | J39: =MAX(IF(A39>=$B$22,J38-$B$24,$B$17),0) -> 43617.721 | K39: =IF(A39>=$B$20,J39*$B$18,0) -> 1744.7088 | L39: =IF(A39=$B$28,$B$27,0) -> 0 | M39: =I39-G39-K39+L39 -> 8558.7241 | N39: =M39-H39 -> 8557.6509 | O39: =IF(N39<0,N39,0) -> 0 | P39: =IF(N39>0,N39+O38,0) -> 8557.6509 | Q39: =$B$25*P39 -> 1968.2597 | R39: =M39-Q39 -> 6590.4644 | S39: =IFERROR(__xludf.DUMMYFUNCTION("IF(ISBETWEEN(A39,$B$22,$B$22+$B$19-1),$B$24,0)"),10904.430218357022) -> 10904.43 | T39: =R39-S39 -> -4313.9659 | U39: =T39+U38 -> 14817.756
A40: 9 | B40: =POWER(1-$B$8,A40)*$B$3 -> 62132.823 | C40: =POWER(1+$B$9,A40) -> 1.3047732 | D40: =$B$7*C40*$B$10 -> 0 | E40: =$B$7*$C40*$B$11 -> 0 | F40: =$B$7*$C40*$B$12 -> 0 | G40: =SUM(D40:F40) -> 0 | H40: =IF(A40=0,$B$17*$B$14*$B$13,H39*$B$13) -> 0.32194785 | I40: =$I$29*B40 -> 10251.916 | J40: =MAX(IF(A40>=$B$22,J39-$B$24,$B$17),0) -> 32713.291 | K40: =IF(A40>=$B$20,J40*$B$18,0) -> 1308.5316 | L40: =IF(A40=$B$28,$B$27,0) -> 0 | M40: =I40-G40-K40+L40 -> 8943.3841 | N40: =M40-H40 -> 8943.0622 | O40: =IF(N40<0,N40,0) -> 0 | P40: =IF(N40>0,N40+O39,0) -> 8943.0622 | Q40: =$B$25*P40 -> 2056.9043 | R40: =M40-Q40 -> 6886.4798 | S40: =IFERROR(__xludf.DUMMYFUNCTION("IF(ISBETWEEN(A40,$B$22,$B$22+$B$19-1),$B$24,0)"),10904.430218357022) -> 10904.43 | T40: =R40-S40 -> -4017.9504 | U40: =T40+U39 -> 10799.805
A41: 10 | B41: =POWER(1-$B$8,A41)*$B$3 -> 61822.158 | C41: =POWER(1+$B$9,A41) -> 1.3439164 | D41: =$B$7*C41*$B$10 -> 0 | E41: =$B$7*$C41*$B$11 -> 0 | F41: =$B$7*$C41*$B$12 -> 0 | G41: =SUM(D41:F41) -> 0 | H41: =IF(A41=0,$B$17*$B$14*$B$13,H40*$B$13) -> 0.096584355 | I41: =$I$29*B41 -> 10200.656 | J41: =MAX(IF(A41>=$B$22,J40-$B$24,$B$17),0) -> 21808.86 | K41: =IF(A41>=$B$20,J41*$B$18,0) -> 872.35442 | L41: =IF(A41=$B$28,$B$27,0) -> 0 | M41: =I41-G41-K41+L41 -> 9328.3017 | N41: =M41-H41 -> 9328.2051 | O41: =IF(N41<0,N41,0) -> 0 | P41: =IF(N41>0,N41+O40,0) -> 9328.2051 | Q41: =$B$25*P41 -> 2145.4872 | R41: =M41-Q41 -> 7182.8145 | S41: =IFERROR(__xludf.DUMMYFUNCTION("IF(ISBETWEEN(A41,$B$22,$B$22+$B$19-1),$B$24,0)"),10904.430218357022) -> 10904.43 | T41: =R41-S41 -> -3721.6157 | U41: =T41+U40 -> 7078.1898
...

Sheet 50% Grant, BVGEC recoup via pro
A2: Capacity Factor | B2: 0.17 | D2: Norfolk | E2: 0.33
A3: System Output | B3: 65000 | D3: BVGEC | E3: 0.33
A4: Hours per Year | B4: 8766 | D4: Community | E4: =1-E2-E3 -> 0.34
A5: System Size | B5: =$B$3/$B$4/$B$2 -> 43.617721
A6: Install Cost | B6: 2.5
A7: Capex | B7: =B5*B6*1000 -> 109044.3
A8: Degradation | B8: 0.005
A9: Inflation | B9: 0.03
A10: Admin Rate | B10: =$E$11 -> 0 | D10: Combined OPEX Rate | E10: 0
A11: Insurance Rate | B11: =$E$11 -> 0 | D11: Individual | E11: =E10/3 -> 0
A12: Maintenance Rate | B12: =$E$11 -> 0
A13: CCA Rate | B13: 0.3
A14: Half Year Rule | B14: 0.5
A15: Grant Rate | B15: 0.5 | L15: Current Bill | M15: ='Bill Comparison'!F28 -> 322479.95
A16: Grant Amount | B16: =B7*B15 -> 54522.151 | L16: New Bill | M16: ='Bill Comparison'!J28 -> 49771.697 | N16: Benefit Dist | O16: Annuity
A17: Net Capex | B17: =B7-B16 -> 54522.151 | L17: Available Savings | M17: ='Bill Comparison'!L28 -> 272708.26 | R17: Bill Saving | S17: =1-(I56+M16)/M15 -> 0.44207903
A18: Debt Rate | B18: 0.04 | L18: Norfolk Bill Savings | M18: =M17-I56 -> 142561.63 | N18: =M18/M19 -> 0.74663227
A19: Debt Term | B19: 10 | L19: Total Benefit | M19: =M18+T56+G56 -> 190939.54 | R19: Effective Savings | S19: =1-(M16+I56-M21)/M15 -> 0.63747117
L20: Norfolk Residual | M20: =M19*0.33-M18 -> -79551.576
L21: Norfolk Total | M21: =M18+M20 -> 63010.049 | N21: =M21/M19 -> 0.33 | O21: =M21/25 -> 2520.402
A22: Repayment Start | B22: 3 | L22: BVGEC Residual | M22: =M19*0.45-G56 -> 85922.795
L23: BVGEC Total | M23: =M22+G56 -> 85922.795 | N23: =M23/M19 -> 0.45 | O23: =M23/25 -> 3436.9118
A24: Repayment Principal | B24: =B17/B19 -> 5452.2151 | L24: Community | M24: =M19-M21-M23 -> 42006.7 | N24: =M24/M19 -> 0.22 | O24: =M24/25 -> 1680.268
A25: Tax Rate | B25: 0.23 | N25: =N21+N23+N24 -> 1
A26: ITC Rate | B26: 0.3
A27: ITC Amount | B27: =B26*B17 -> 16356.645 | L27: Utilization | M27: =M19/M17 -> 0.70016048
A28: ITC year | B28: 1
H29: Effective PPA | I29: 0.085
A30: Year | B30: Effective Output | C30: Escalation Factor | D30: Admin Cost | E30: Insurance Cost | F30: Maintenance Cost | G30: OPEX | H30: Capital Cost Allowance | I30: Revenue | J30: Debt Principal | K30: Debt Interest | L30: ITC Credit | M30: Pre Tax Operating Cashflow | N30: Taxable Income Before Carry Forward Loss | O30: Carry Forward Losses | P30: Taxable Income After Carry Forward Loss | Q30: Tax | R30: After Tax Income | S30: Principal Repayent | T30: Cashflow To Equity
A31: 0 | B31: =POWER(1-$B$8,A31)*$B$3 -> 65000 | C31: =POWER(1+$B$9,A31) -> 1 | D31: =$B$7*C31*$B$10 -> 0 | E31: =$B$7*$C31*$B$11 -> 0 | F31: =$B$7*$C31*$B$12 -> 0 | G31: =SUM(D31:F31) -> 0 | H31: =IF(A31=0,$B$17*$B$14*$B$13,H30*$B$13) -> 8178.3227 | I31: =$I$29*B31 -> 5525 | J31: =MAX(IF(A31>=$B$22,J30-$B$24,$B$17),0) -> 54522.151 | K31: =IF(A31>=$B$20,J31*$B$18,0) -> 2180.886 | L31: =IF(A31=$B$28,$B$27,0) -> 0 | M31: =I31-G31-K31+L31 -> 3344.114 | N31: =M31-H31 -> -4834.2087 | O31: =IF(N31<0,N31,0) -> -4834.2087 | P31: =N31-O31 -> 0 | Q31: =$B$25*P31 -> 0 | R31: =M31-Q31 -> 3344.114 | S31: =IFERROR(__xludf.DUMMYFUNCTION("IF(ISBETWEEN(A31,$B$22,$B$22+$B$19-1),$B$24,0)"),0.0) -> 0 | T31: =R31-S31 -> 3344.114 | U31: =T31 -> 3344.114
A32: 1 | B32: =POWER(1-$B$8,A32)*$B$3 -> 64675 | C32: =POWER(1+$B$9,A32) -> 1.03 | D32: =$B$7*C32*$B$10 -> 0 | E32: =$B$7*$C32*$B$11 -> 0 | F32: =$B$7*$C32*$B$12 -> 0 | G32: =SUM(D32:F32) -> 0 | H32: =IF(A32=0,$B$17*$B$14*$B$13,H31*$B$13) -> 2453.4968 | I32: =$I$29*B32 -> 5497.375 | J32: =MAX(IF(A32>=$B$22,J31-$B$24,$B$17),0) -> 54522.151 | K32: =IF(A32>=$B$20,J32*$B$18,0) -> 2180.886 | L32: =IF(A32=$B$28,$B$27,0) -> 16356.645 | M32: =I32-G32-K32+L32 -> 19673.134 | N32: =M32-H32 -> 17219.637 | O32: =IF(N32<0,N32,0) -> 0 | P32: =IF(N32>0,N32+O31,0) -> 12385.429 | Q32: =$B$25*P32 -> 2848.6486 | R32: =M32-Q32 -> 16824.486 | S32: =IFERROR(__xludf.DUMMYFUNCTION("IF(ISBETWEEN(A32,$B$22,$B$22+$B$19-1),$B$24,0)"),0.0) -> 0 | T32: =R32-S32 -> 16824.486 | U32: =T32+U31 -> 20168.6
A33: 2 | B33: =POWER(1-$B$8,A33)*$B$3 -> 64351.625 | C33: =POWER(1+$B$9,A33) -> 1.0609 | D33: =$B$7*C33*$B$10 -> 0 | E33: =$B$7*$C33*$B$11 -> 0 | F33: =$B$7*$C33*$B$12 -> 0 | G33: =SUM(D33:F33) -> 0 | H33: =IF(A33=0,$B$17*$B$14*$B$13,H32*$B$13) -> 736.04904 | I33: =$I$29*B33 -> 5469.8881 | J33: =MAX(IF(A33>=$B$22,J32-$B$24,$B$17),0) -> 54522.151 | K33: =IF(A33>=$B$20,J33*$B$18,0) -> 2180.886 | L33: =IF(A33=$B$28,$B$27,0) -> 0 | M33: =I33-G33-K33+L33 -> 3289.0021 | N33: =M33-H33 -> 2552.953 | O33: =IF(N33<0,N33,0) -> 0 | P33: =IF(N33>0,N33+O32,0) -> 2552.953 | Q33: =$B$25*P33 -> 587.1792 | R33: =M33-Q33 -> 2701.8229 | S33: =IFERROR(__xludf.DUMMYFUNCTION("IF(ISBETWEEN(A33,$B$22,$B$22+$B$19-1),$B$24,0)"),0.0) -> 0 | T33: =R33-S33 -> 2701.8229 | U33: =T33+U32 -> 22870.423
A34: 3 | B34: =POWER(1-$B$8,A34)*$B$3 -> 64029.867 | C34: =POWER(1+$B$9,A34) -> 1.092727 | D34: =$B$7*C34*$B$10 -> 0 | E34: =$B$7*$C34*$B$11 -> 0 | F34: =$B$7*$C34*$B$12 -> 0 | G34: =SUM(D34:F34) -> 0 | H34: =IF(A34=0,$B$17*$B$14*$B$13,H33*$B$13) -> 220.81471 | I34: =$I$29*B34 -> 5442.5387 | J34: =MAX(IF(A34>=$B$22,J33-$B$24,$B$17),0) -> 49069.936 | K34: =IF(A34>=$B$20,J34*$B$18,0) -> 1962.7974 | L34: =IF(A34=$B$28,$B$27,0) -> 0 | M34: =I34-G34-K34+L34 -> 3479.7412 | N34: =M34-H34 -> 3258.9265 | O34: =IF(N34<0,N34,0) -> 0 | P34: =IF(N34>0,N34+O33,0) -> 3258.9265 | Q34: =$B$25*P34 -> 749.5531 | R34: =M34-Q34 -> 2730.1881 | S34: =IFERROR(__xludf.DUMMYFUNCTION("IF(ISBETWEEN(A34,$B$22,$B$22+$B$19-1),$B$24,0)"),5452.215109178511) -> 5452.2151 | T34: =R34-S34 -> -2722.027 | U34: =T34+U33 -> 20148.396
A35: 4 | B35: =POWER(1-$B$8,A35)*$B$3 -> 63709.718 | C35: =POWER(1+$B$9,A35) -> 1.1255088 | D35: =$B$7*C35*$B$10 -> 0 | E35: =$B$7*$C35*$B$11 -> 0 | F35: =$B$7*$C35*$B$12 -> 0 | G35: =SUM(D35:F35) -> 0 | H35: =IF(A35=0,$B$17*$B$14*$B$13,H34*$B$13) -> 66.244414 | I35: =$I$29*B35 -> 5415.326 | J35: =MAX(IF(A35>=$B$22,J34-$B$24,$B$17),0) -> 43617.721 | K35: =IF(A35>=$B$20,J35*$B$18,0) -> 1744.7088 | L35: =IF(A35=$B$28,$B$27,0) -> 0 | M35: =I35-G35-K35+L35 -> 3670.6172 | N35: =M35-H35 -> 3604.3727 | O35: =IF(N35<0,N35,0) -> 0 | P35: =IF(N35>0,N35+O34,0) -> 3604.3727 | Q35: =$B$25*P35 -> 829.00573 | R35: =M35-Q35 -> 2841.6114 | S35: =IFERROR(__xludf.DUMMYFUNCTION("IF(ISBETWEEN(A35,$B$22,$B$22+$B$19-1),$B$24,0)"),5452.215109178511) -> 5452.2151 | T35: =R35-S35 -> -2610.6037 | U35: =T35+U34 -> 17537.792
A36: 5 | B36: =POWER(1-$B$8,A36)*$B$3 -> 63391.169 | C36: =POWER(1+$B$9,A36) -> 1.1592741 | D36: =$B$7*C36*$B$10 -> 0 | E36: =$B$7*$C36*$B$11 -> 0 | F36: =$B$7*$C36*$B$12 -> 0 | G36: =SUM(D36:F36) -> 0 | H36: =IF(A36=0,$B$17*$B$14*$B$13,H35*$B$13) -> 19.873324 | I36: =$I$29*B36 -> 5388.2494 | J36: =MAX(IF(A36>=$B$22,J35-$B$24,$B$17),0) -> 38165.506 | K36: =IF(A36>=$B$20,J36*$B$18,0) -> 1526.6202 | L36: =IF(A36=$B$28,$B$27,0) -> 0 | M36: =I36-G36-K36+L36 -> 3861.6291 | N36: =M36-H36 -> 3841.7558 | O36: =IF(N36<0,N36,0) -> 0 | P36: =IF(N36>0,N36+O35,0) -> 3841.7558 | Q36: =$B$25*P36 -> 883.60384 | R36: =M36-Q36 -> 2978.0253 | S36: =IFERROR(__xludf.DUMMYFUNCTION("IF(ISBETWEEN(A36,$B$22,$B$22+$B$19-1),$B$24,0)"),5452.215109178511) -> 5452.2151 | T36: =R36-S36 -> -2474.1898 | U36: =T36+U35 -> 15063.602
A37: 6 | B37: =POWER(1-$B$8,A37)*$B$3 -> 63074.213 | C37: =POWER(1+$B$9,A37) -> 1.1940523 | D37: =$B$7*C37*$B$10 -> 0 | E37: =$B$7*$C37*$B$11 -> 0 | F37: =$B$7*$C37*$B$12 -> 0 | G37: =SUM(D37:F37) -> 0 | H37: =IF(A37=0,$B$17*$B$14*$B$13,H36*$B$13) -> 5.9619972 | I37: =$I$29*B37 -> 5361.3081 | J37: =MAX(IF(A37>=$B$22,J36-$B$24,$B$17),0) -> 32713.291 | K37: =IF(A37>=$B$20,J37*$B$18,0) -> 1308.5316 | L37: =IF(A37=$B$28,$B$27,0) -> 0 | M37: =I37-G37-K37+L37 -> 4052.7765 | N37: =M37-H37 -> 4046.8145 | O37: =IF(N37<0,N37,0) -> 0 | P37: =IF(N37>0,N37+O36,0) -> 4046.8145 | Q37: =$B$25*P37 -> 930.76733 | R37: =M37-Q37 -> 3122.0092 | S37: =IFERROR(__xludf.DUMMYFUNCTION("IF(ISBETWEEN(A37,$B$22,$B$22+$B$19-1),$B$24,0)"),5452.215109178511) -> 5452.2151 | T37: =R37-S37 -> -2330.206 | U37: =T37+U36 -> 12733.396
A38: 7 | B38: =POWER(1-$B$8,A38)*$B$3 -> 62758.842 | C38: =POWER(1+$B$9,A38) -> 1.2298739 | D38: =$B$7*C38*$B$10 -> 0 | E38: =$B$7*$C38*$B$11 -> 0 | F38: =$B$7*$C38*$B$12 -> 0 | G38: =SUM(D38:F38) -> 0 | H38: =IF(A38=0,$B$17*$B$14*$B$13,H37*$B$13) -> 1.7885992 | I38: =$I$29*B38 -> 5334.5016 | J38: =MAX(IF(A38>=$B$22,J37-$B$24,$B$17),0) -> 27261.076 | K38: =IF(A38>=$B$20,J38*$B$18,0) -> 1090.443 | L38: =IF(A38=$B$28,$B$27,0) -> 0 | M38: =I38-G38-K38+L38 -> 4244.0586 | N38: =M38-H38 -> 4242.27 | O38: =IF(N38<0,N38,0) -> 0 | P38: =IF(N38>0,N38+O37,0) -> 4242.27 | Q38: =$B$25*P38 -> 975.72209 | R38: =M38-Q38 -> 3268.3365 | S38: =IFERROR(__xludf.DUMMYFUNCTION("IF(ISBETWEEN(A38,$B$22,$B$22+$B$19-1),$B$24,0)"),5452.215109178511) -> 5452.2151 | T38: =R38-S38 -> -2183.8786 | U38: =T38+U37 -> 10549.517
A39: 8 | B39: =POWER(1-$B$8,A39)*$B$3 -> 62445.048 | C39: =POWER(1+$B$9,A39) -> 1.2667701 | D39: =$B$7*C39*$B$10 -> 0 | E39: =$B$7*$C39*$B$11 -> 0 | F39: =$B$7*$C39*$B$12 -> 0 | G39: =SUM(D39:F39) -> 0 | H39: =IF(A39=0,$B$17*$B$14*$B$13,H38*$B$13) -> 0.53657975 | I39: =$I$29*B39 -> 5307.8291 | J39: =MAX(IF(A39>=$B$22,J38-$B$24,$B$17),0) -> 21808.86 | K39: =IF(A39>=$B$20,J39*$B$18,0) -> 872.35442 | L39: =IF(A39=$B$28,$B$27,0) -> 0 | M39: =I39-G39-K39+L39 -> 4435.4746 | N39: =M39-H39 -> 4434.9381 | O39: =IF(N39<0,N39,0) -> 0 | P39: =IF(N39>0,N39+O38,0) -> 4434.9381 | Q39: =$B$25*P39 -> 1020.0358 | R39: =M39-Q39 -> 3415.4389 | S39: =IFERROR(__xludf.DUMMYFUNCTION("IF(ISBETWEEN(A39,$B$22,$B$22+$B$19-1),$B$24,0)"),5452.215109178511) -> 5452.2151 | T39: =R39-S39 -> -2036.7762 | U39: =T39+U38 -> 8512.7412
A40: 9 | B40: =POWER(1-$B$8,A40)*$B$3 -> 62132.823 | C40: =POWER(1+$B$9,A40) -> 1.3047732 | D40: =$B$7*C40*$B$10 -> 0 | E40: =$B$7*$C40*$B$11 -> 0 | F40: =$B$7*$C40*$B$12 -> 0 | G40: =SUM(D40:F40) -> 0 | H40: =IF(A40=0,$B$17*$B$14*$B$13,H39*$B$13) -> 0.16097392 | I40: =$I$29*B40 -> 5281.2899 | J40: =MAX(IF(A40>=$B$22,J39-$B$24,$B$17),0) -> 16356.645 | K40: =IF(A40>=$B$20,J40*$B$18,0) -> 654.26581 | L40: =IF(A40=$B$28,$B$27,0) -> 0 | M40: =I40-G40-K40+L40 -> 4627.0241 | N40: =M40-H40 -> 4626.8631 | O40: =IF(N40<0,N40,0) -> 0 | P40: =IF(N40>0,N40+O39,0) -> 4626.8631 | Q40: =$B$25*P40 -> 1064.1785 | R40: =M40-Q40 -> 3562.8456 | S40: =IFERROR(__xludf.DUMMYFUNCTION("IF(ISBETWEEN(A40,$B$22,$B$22+$B$19-1),$B$24,0)"),5452.215109178511) -> 5452.2151 | T40: =R40-S40 -> -1889.3695 | U40: =T40+U39 -> 6623.3717
A41: 10 | B41: =POWER(1-$B$8,A41)*$B$3 -> 61822.158 | C41: =POWER(1+$B$9,A41) -> 1.3439164 | D41: =$B$7*C41*$B$10 -> 0 | E41: =$B$7*$C41*$B$11 -> 0 | F41: =$B$7*$C41*$B$12 -> 0 | G41: =SUM(D41:F41) -> 0 | H41: =IF(A41=0,$B$17*$B$14*$B$13,H40*$B$13) -> 0.048292177 | I41: =$I$29*B41 -> 5254.8835 | J41: =MAX(IF(A41>=$B$22,J40-$B$24,$B$17),0) -> 10904.43 | K41: =IF(A41>=$B$20,J41*$B$18,0) -> 436.17721 | L41: =IF(A41=$B$28,$B$27,0) -> 0 | M41: =I41-G41-K41+L41 -> 4818.7063 | N41: =M41-H41 -> 4818.658 | O41: =IF(N41<0,N41,0) -> 0 | P41: =IF(N41>0,N41+O40,0) -> 4818.658 | Q41: =$B$25*P41 -> 1108.2913 | R41: =M41-Q41 -> 3710.4149 | S41: =IFERROR(__xludf.DUMMYFUNCTION("IF(ISBETWEEN(A41,$B$22,$B$22+$B$19-1),$B$24,0)"),5452.215109178511) -> 5452.2151 | T41: =R41-S41 -> -1741.8002 | U41: =T41+U40 -> 4881.5715
...

Sheet 50% Grant, flow through BVGEC
A2: Capacity Factor | B2: 0.17 | D2: Norfolk | E2: 0.33
A3: System Output | B3: 65000 | D3: BVGEC | E3: 0.33
A4: Hours per Year | B4: 8766 | D4: Community | E4: =1-E2-E3 -> 0.34
A5: System Size | B5: =$B$3/$B$4/$B$2 -> 43.617721
A6: Install Cost | B6: 2.5
A7: Capex | B7: =B5*B6*1000 -> 109044.3
A8: Degradation | B8: 0.005
A9: Inflation | B9: 0.03
A10: Admin Rate | B10: =$E$11 -> 0.014 | D10: Combined OPEX Rate | E10: 0.042
A11: Insurance Rate | B11: =$E$11 -> 0.014 | D11: Individual | E11: =E10/3 -> 0.014
A12: Maintenance Rate | B12: =$E$11 -> 0.014
A13: CCA Rate | B13: 0.3
A14: Half Year Rule | B14: 0.5
A15: Grant Rate | B15: 0.5 | L15: Current Bill | M15: ='Bill Comparison'!F28 -> 322479.95
A16: Grant Amount | B16: =B7*B15 -> 54522.151 | L16: New Bill | M16: ='Bill Comparison'!J28 -> 49771.697 | N16: Benefit Dist | O16: Annuity
A17: Net Capex | B17: =B7-B16 -> 54522.151 | L17: Available Savings | M17: ='Bill Comparison'!L28 -> 272708.26 | R17: Bill Saving | S17: =1-(I56+M16)/M15 -> 0.038498498
A18: Debt Rate | B18: 0.04 | L18: Norfolk Bill Savings | M18: =M17-I56 -> 12414.994 | N18: =M18/M19 -> 0.06225837
A19: Debt Term | B19: 10 | L19: Total Benefit | M19: =M18+T56+G56 -> 199410.84 | R19: Effective Savings | S19: =1-(M16+I56-M21)/M15 -> 0.24255948
L20: Norfolk Residual | M20: =M19*0.33-M18 -> 53390.583
L21: Norfolk Total | M21: =M18+M20 -> 65805.577 | N21: =M21/M19 -> 0.33 | O21: =M21/25 -> 2632.2231
A22: Repayment Start | B22: 3 | L22: BVGEC Residual | M22: =M19*0.45-G56 -> -77243.474
L23: BVGEC Total | M23: =M22+G56 -> 89734.878 | N23: =M23/M19 -> 0.45 | O23: =M23/25 -> 3589.3951
A24: Repayment Principal | B24: =B17/B19 -> 5452.2151 | L24: Community | M24: =M19-M21-M23 -> 43870.385 | N24: =M24/M19 -> 0.22 | O24: =M24/25 -> 1754.8154
A25: Tax Rate | B25: 0.23 | N25: =N21+N23+N24 -> 1
A26: ITC Rate | B26: 0.3
A27: ITC Amount | B27: =B26*B17 -> 16356.645 | L27: Utilization | M27: =M19/M17 -> 0.73122406
A28: ITC year | B28: 1
H29: Effective PPA | I29: 0.17
A30: Year | B30: Effective Output | C30: Escalation Factor | D30: Admin Cost | E30: Insurance Cost | F30: Maintenance Cost | G30: OPEX | H30: Capital Cost Allowance | I30: Revenue | J30: Debt Principal | K30: Debt Interest | L30: ITC Credit | M30: Pre Tax Operating Cashflow | N30: Taxable Income Before Carry Forward Loss | O30: Carry Forward Losses | P30: Taxable Income After Carry Forward Loss | Q30: Tax | R30: After Tax Income | S30: Principal Repayent | T30: Cashflow To Equity
A31: 0 | B31: =POWER(1-$B$8,A31)*$B$3 -> 65000 | C31: =POWER(1+$B$9,A31) -> 1 | D31: =$B$7*C31*$B$10 -> 1526.6202 | E31: =$B$7*$C31*$B$11 -> 1526.6202 | F31: =$B$7*$C31*$B$12 -> 1526.6202 | G31: =SUM(D31:F31) -> 4579.8607 | H31: =IF(A31=0,$B$17*$B$14*$B$13,H30*$B$13) -> 8178.3227 | I31: =$I$29*B31 -> 11050 | J31: =MAX(IF(A31>=$B$22,J30-$B$24,$B$17),0) -> 54522.151 | K31: =IF(A31>=$B$20,J31*$B$18,0) -> 2180.886 | L31: =IF(A31=$B$28,$B$27,0) -> 0 | M31: =I31-G31-K31+L31 -> 4289.2533 | N31: =M31-H31 -> -3889.0694 | O31: =IF(N31<0,N31,0) -> -3889.0694 | P31: =N31-O31 -> 0 | Q31: =$B$25*P31 -> 0 | R31: =M31-Q31 -> 4289.2533 | S31: =IFERROR(__xludf.DUMMYFUNCTION("IF(ISBETWEEN(A31,$B$22,$B$22+$B$19-1),$B$24,0)"),0.0) -> 0 | T31: =R31-S31 -> 4289.2533 | U31: =T31 -> 4289.2533
A32: 1 | B32: =POWER(1-$B$8,A32)*$B$3 -> 64675 | C32: =POWER(1+$B$9,A32) -> 1.03 | D32: =$B$7*C32*$B$10 -> 1572.4188 | E32: =$B$7*$C32*$B$11 -> 1572.4188 | F32: =$B$7*$C32*$B$12 -> 1572.4188 | G32: =SUM(D32:F32) -> 4717.2565 | H32: =IF(A32=0,$B$17*$B$14*$B$13,H31*$B$13) -> 2453.4968 | I32: =$I$29*B32 -> 10994.75 | J32: =MAX(IF(A32>=$B$22,J31-$B$24,$B$17),0) -> 54522.151 | K32: =IF(A32>=$B$20,J32*$B$18,0) -> 2180.886 | L32: =IF(A32=$B$28,$B$27,0) -> 16356.645 | M32: =I32-G32-K32+L32 -> 20453.253 | N32: =M32-H32 -> 17999.756 | O32: =IF(N32<0,N32,0) -> 0 | P32: =IF(N32>0,N32+O31,0) -> 14110.687 | Q32: =$B$25*P32 -> 3245.4579 | R32: =M32-Q32 -> 17207.795 | S32: =IFERROR(__xludf.DUMMYFUNCTION("IF(ISBETWEEN(A32,$B$22,$B$22+$B$19-1),$B$24,0)"),0.0) -> 0 | T32: =R32-S32 -> 17207.795 | U32: =T32+U31 -> 21497.048
A33: 2 | B33: =POWER(1-$B$8,A33)*$B$3 -> 64351.625 | C33: =POWER(1+$B$9,A33) -> 1.0609 | D33: =$B$7*C33*$B$10 -> 1619.5914 | E33: =$B$7*$C33*$B$11 -> 1619.5914 | F33: =$B$7*$C33*$B$12 -> 1619.5914 | G33: =SUM(D33:F33) -> 4858.7742 | H33: =IF(A33=0,$B$17*$B$14*$B$13,H32*$B$13) -> 736.04904 | I33: =$I$29*B33 -> 10939.776 | J33: =MAX(IF(A33>=$B$22,J32-$B$24,$B$17),0) -> 54522.151 | K33: =IF(A33>=$B$20,J33*$B$18,0) -> 2180.886 | L33: =IF(A33=$B$28,$B$27,0) -> 0 | M33: =I33-G33-K33+L33 -> 3900.116 | N33: =M33-H33 -> 3164.067 | O33: =IF(N33<0,N33,0) -> 0 | P33: =IF(N33>0,N33+O32,0) -> 3164.067 | Q33: =$B$25*P33 -> 727.7354 | R33: =M33-Q33 -> 3172.3806 | S33: =IFERROR(__xludf.DUMMYFUNCTION("IF(ISBETWEEN(A33,$B$22,$B$22+$B$19-1),$B$24,0)"),0.0) -> 0 | T33: =R33-S33 -> 3172.3806 | U33: =T33+U32 -> 24669.429
A34: 3 | B34: =POWER(1-$B$8,A34)*$B$3 -> 64029.867 | C34: =POWER(1+$B$9,A34) -> 1.092727 | D34: =$B$7*C34*$B$10 -> 1668.1791 | E34: =$B$7*$C34*$B$11 -> 1668.1791 | F34: =$B$7*$C34*$B$12 -> 1668.1791 | G34: =SUM(D34:F34) -> 5004.5374 | H34: =IF(A34=0,$B$17*$B$14*$B$13,H33*$B$13) -> 220.81471 | I34: =$I$29*B34 -> 10885.077 | J34: =MAX(IF(A34>=$B$22,J33-$B$24,$B$17),0) -> 49069.936 | K34: =IF(A34>=$B$20,J34*$B$18,0) -> 1962.7974 | L34: =IF(A34=$B$28,$B$27,0) -> 0 | M34: =I34-G34-K34+L34 -> 3917.7425 | N34: =M34-H34 -> 3696.9278 | O34: =IF(N34<0,N34,0) -> 0 | P34: =IF(N34>0,N34+O33,0) -> 3696.9278 | Q34: =$B$25*P34 -> 850.29339 | R34: =M34-Q34 -> 3067.4491 | S34: =IFERROR(__xludf.DUMMYFUNCTION("IF(ISBETWEEN(A34,$B$22,$B$22+$B$19-1),$B$24,0)"),5452.215109178511) -> 5452.2151 | T34: =R34-S34 -> -2384.766 | U34: =T34+U33 -> 22284.663
A35: 4 | B35: =POWER(1-$B$8,A35)*$B$3 -> 63709.718 | C35: =POWER(1+$B$9,A35) -> 1.1255088 | D35: =$B$7*C35*$B$10 -> 1718.2245 | E35: =$B$7*$C35*$B$11 -> 1718.2245 | F35: =$B$7*$C35*$B$12 -> 1718.2245 | G35: =SUM(D35:F35) -> 5154.6736 | H35: =IF(A35=0,$B$17*$B$14*$B$13,H34*$B$13) -> 66.244414 | I35: =$I$29*B35 -> 10830.652 | J35: =MAX(IF(A35>=$B$22,J34-$B$24,$B$17),0) -> 43617.721 | K35: =IF(A35>=$B$20,J35*$B$18,0) -> 1744.7088 | L35: =IF(A35=$B$28,$B$27,0) -> 0 | M35: =I35-G35-K35+L35 -> 3931.2696 | N35: =M35-H35 -> 3865.0252 | O35: =IF(N35<0,N35,0) -> 0 | P35: =IF(N35>0,N35+O34,0) -> 3865.0252 | Q35: =$B$25*P35 -> 888.95579 | R35: =M35-Q35 -> 3042.3138 | S35: =IFERROR(__xludf.DUMMYFUNCTION("IF(ISBETWEEN(A35,$B$22,$B$22+$B$19-1),$B$24,0)"),5452.215109178511) -> 5452.2151 | T35: =R35-S35 -> -2409.9013 | U35: =T35+U34 -> 19874.761
A36: 5 | B36: =POWER(1-$B$8,A36)*$B$3 -> 63391.169 | C36: =POWER(1+$B$9,A36) -> 1.1592741 | D36: =$B$7*C36*$B$10 -> 1769.7713 | E36: =$B$7*$C36*$B$11 -> 1769.7713 | F36: =$B$7*$C36*$B$12 -> 1769.7713 | G36: =SUM(D36:F36) -> 5309.3138 | H36: =IF(A36=0,$B$17*$B$14*$B$13,H35*$B$13) -> 19.873324 | I36: =$I$29*B36 -> 10776.499 | J36: =MAX(IF(A36>=$B$22,J35-$B$24,$B$17),0) -> 38165.506 | K36: =IF(A36>=$B$20,J36*$B$18,0) -> 1526.6202 | L36: =IF(A36=$B$28,$B$27,0) -> 0 | M36: =I36-G36-K36+L36 -> 3940.5647 | N36: =M36-H36 -> 3920.6914 | O36: =IF(N36<0,N36,0) -> 0 | P36: =IF(N36>0,N36+O35,0) -> 3920.6914 | Q36: =$B$25*P36 -> 901.75902 | R36: =M36-Q36 -> 3038.8057 | S36: =IFERROR(__xludf.DUMMYFUNCTION("IF(ISBETWEEN(A36,$B$22,$B$22+$B$19-1),$B$24,0)"),5452.215109178511) -> 5452.2151 | T36: =R36-S36 -> -2413.4094 | U36: =T36+U35 -> 17461.352
A37: 6 | B37: =POWER(1-$B$8,A37)*$B$3 -> 63074.213 | C37: =POWER(1+$B$9,A37) -> 1.1940523 | D37: =$B$7*C37*$B$10 -> 1822.8644 | E37: =$B$7*$C37*$B$11 -> 1822.8644 | F37: =$B$7*$C37*$B$12 -> 1822.8644 | G37: =SUM(D37:F37) -> 5468.5932 | H37: =IF(A37=0,$B$17*$B$14*$B$13,H36*$B$13) -> 5.9619972 | I37: =$I$29*B37 -> 10722.616 | J37: =MAX(IF(A37>=$B$22,J36-$B$24,$B$17),0) -> 32713.291 | K37: =IF(A37>=$B$20,J37*$B$18,0) -> 1308.5316 | L37: =IF(A37=$B$28,$B$27,0) -> 0 | M37: =I37-G37-K37+L37 -> 3945.4914 | N37: =M37-H37 -> 3939.5294 | O37: =IF(N37<0,N37,0) -> 0 | P37: =IF(N37>0,N37+O36,0) -> 3939.5294 | Q37: =$B$25*P37 -> 906.09177 | R37: =M37-Q37 -> 3039.3997 | S37: =IFERROR(__xludf.DUMMYFUNCTION("IF(ISBETWEEN(A37,$B$22,$B$22+$B$19-1),$B$24,0)"),5452.215109178511) -> 5452.2151 | T37: =R37-S37 -> -2412.8155 | U37: =T37+U36 -> 15048.537
A38: 7 | B38: =POWER(1-$B$8,A38)*$B$3 -> 62758.842 | C38: =POWER(1+$B$9,A38) -> 1.2298739 | D38: =$B$7*C38*$B$10 -> 1877.5503 | E38: =$B$7*$C38*$B$11 -> 1877.5503 | F38: =$B$7*$C38*$B$12 -> 1877.5503 | G38: =SUM(D38:F38) -> 5632.651 | H38: =IF(A38=0,$B$17*$B$14*$B$13,H37*$B$13) -> 1.7885992 | I38: =$I$29*B38 -> 10669.003 | J38: =MAX(IF(A38>=$B$22,J37-$B$24,$B$17),0) -> 27261.076 | K38: =IF(A38>=$B$20,J38*$B$18,0) -> 1090.443 | L38: =IF(A38=$B$28,$B$27,0) -> 0 | M38: =I38-G38-K38+L38 -> 3945.9092 | N38: =M38-H38 -> 3944.1206 | O38: =IF(N38<0,N38,0) -> 0 | P38: =IF(N38>0,N38+O37,0) -> 3944.1206 | Q38: =$B$25*P38 -> 907.14773 | R38: =M38-Q38 -> 3038.7614 | S38: =IFERROR(__xludf.DUMMYFUNCTION("IF(ISBETWEEN(A38,$B$22,$B$22+$B$19-1),$B$24,0)"),5452.215109178511) -> 5452.2151 | T38: =R38-S38 -> -2413.4537 | U38: =T38+U37 -> 12635.083
A39: 8 | B39: =POWER(1-$B$8,A39)*$B$3 -> 62445.048 | C39: =POWER(1+$B$9,A39) -> 1.2667701 | D39: =$B$7*C39*$B$10 -> 1933.8768 | E39: =$B$7*$C39*$B$11 -> 1933.8768 | F39: =$B$7*$C39*$B$12 -> 1933.8768 | G39: =SUM(D39:F39) -> 5801.6305 | H39: =IF(A39=0,$B$17*$B$14*$B$13,H38*$B$13) -> 0.53657975 | I39: =$I$29*B39 -> 10615.658 | J39: =MAX(IF(A39>=$B$22,J38-$B$24,$B$17),0) -> 21808.86 | K39: =IF(A39>=$B$20,J39*$B$18,0) -> 872.35442 | L39: =IF(A39=$B$28,$B$27,0) -> 0 | M39: =I39-G39-K39+L39 -> 3941.6732 | N39: =M39-H39 -> 3941.1366 | O39: =IF(N39<0,N39,0) -> 0 | P39: =IF(N39>0,N39+O38,0) -> 3941.1366 | Q39: =$B$25*P39 -> 906.46143 | R39: =M39-Q39 -> 3035.2118 | S39: =IFERROR(__xludf.DUMMYFUNCTION("IF(ISBETWEEN(A39,$B$22,$B$22+$B$19-1),$B$24,0)"),5452.215109178511) -> 5452.2151 | T39: =R39-S39 -> -2417.0033 | U39: =T39+U38 -> 10218.08
A40: 9 | B40: =POWER(1-$B$8,A40)*$B$3 -> 62132.823 | C40: =POWER(1+$B$9,A40) -> 1.3047732 | D40: =$B$7*C40*$B$10 -> 1991.8931 | E40: =$B$7*$C40*$B$11 -> 1991.8931 | F40: =$B$7*$C40*$B$12 -> 1991.8931 | G40: =SUM(D40:F40) -> 5975.6794 | H40: =IF(A40=0,$B$17*$B$14*$B$13,H39*$B$13) -> 0.16097392 | I40: =$I$29*B40 -> 10562.58 | J40: =MAX(IF(A40>=$B$22,J39-$B$24,$B$17),0) -> 16356.645 | K40: =IF(A40>=$B$20,J40*$B$18,0) -> 654.26581 | L40: =IF(A40=$B$28,$B$27,0) -> 0 | M40: =I40-G40-K40+L40 -> 3932.6346 | N40: =M40-H40 -> 3932.4736 | O40: =IF(N40<0,N40,0) -> 0 | P40: =IF(N40>0,N40+O39,0) -> 3932.4736 | Q40: =$B$25*P40 -> 904.46894 | R40: =M40-Q40 -> 3028.1657 | S40: =IFERROR(__xludf.DUMMYFUNCTION("IF(ISBETWEEN(A40,$B$22,$B$22+$B$19-1),$B$24,0)"),5452.215109178511) -> 5452.2151 | T40: =R40-S40 -> -2424.0494 | U40: =T40+U39 -> 7794.0301
A41: 10 | B41: =POWER(1-$B$8,A41)*$B$3 -> 61822.158 | C41: =POWER(1+$B$9,A41) -> 1.3439164 | D41: =$B$7*C41*$B$10 -> 2051.6499 | E41: =$B$7*$C41*$B$11 -> 2051.6499 | F41: =$B$7*$C41*$B$12 -> 2051.6499 | G41: =SUM(D41:F41) -> 6154.9498 | H41: =IF(A41=0,$B$17*$B$14*$B$13,H40*$B$13) -> 0.048292177 | I41: =$I$29*B41 -> 10509.767 | J41: =MAX(IF(A41>=$B$22,J40-$B$24,$B$17),0) -> 10904.43 | K41: =IF(A41>=$B$20,J41*$B$18,0) -> 436.17721 | L41: =IF(A41=$B$28,$B$27,0) -> 0 | M41: =I41-G41-K41+L41 -> 3918.6399 | N41: =M41-H41 -> 3918.5916 | O41: =IF(N41<0,N41,0) -> 0 | P41: =IF(N41>0,N41+O40,0) -> 3918.5916 | Q41: =$B$25*P41 -> 901.27608 | R41: =M41-Q41 -> 3017.3639 | S41: =IFERROR(__xludf.DUMMYFUNCTION("IF(ISBETWEEN(A41,$B$22,$B$22+$B$19-1),$B$24,0)"),5452.215109178511) -> 5452.2151 | T41: =R41-S41 -> -2434.8513 | U41: =T41+U40 -> 5359.1789
...

Sheet 50% Grant, BVGEC recoup via OPE
A2: Capacity Factor | B2: 0.17 | D2: Norfolk | E2: 0.33
A3: System Output | B3: 65000 | D3: BVGEC | E3: 0.33
A4: Hours per Year | B4: 8766 | D4: Community | E4: =1-E2-E3 -> 0.34
A5: System Size | B5: =$B$3/$B$4/$B$2 -> 43.617721
A6: Install Cost | B6: 2.5
A7: Capex | B7: =B5*B6*1000 -> 109044.3
A8: Degradation | B8: 0.005
A9: Inflation | B9: 0.03
A10: Admin Rate | B10: =$E$11 -> 0.0075 | D10: Combined OPEX Rate | E10: 0.0225
A11: Insurance Rate | B11: =$E$11 -> 0.0075 | D11: Individual | E11: =E10/3 -> 0.0075
A12: Maintenance Rate | B12: =$E$11 -> 0.0075
A13: CCA Rate | B13: 0.3
A14: Half Year Rule | B14: 0.5
A15: Grant Rate | B15: 0.5 | L15: Current Bill | M15: ='Bill Comparison'!F28 -> 322479.95
A16: Grant Amount | B16: =B7*B15 -> 54522.151 | L16: New Bill | M16: ='Bill Comparison'!J28 -> 49771.697 | N16: Benefit Dist | O16: Annuity
A17: Net Capex | B17: =B7-B16 -> 54522.151 | L17: Available Savings | M17: ='Bill Comparison'!L28 -> 272708.26 | R17: Bill Saving | S17: =1-(I53+M16)/M15 -> 0.2640288
A18: Debt Rate | B18: 0.04 | L18: Norfolk Savings | M18: =M17-I53 -> 85143.994 | N18: =M18/M19 -> 0.41871599 | O18: =M18/25 -> 3405.7597
A19: Debt Term | B19: 10 | L19: Total Benefit | M19: =M18+T53+G53 -> 203345.45
A20: Repayment Start | B20: 3 | L20: BVGEC | M20: =G53 -> 89452.688 | N20: =M20/M19 -> 0.43990503 | O20: =M20/25 -> 3578.1075
A21: Repayment Principal | B21: =B17/B19 -> 5452.2151 | L21: Community | M21: =M19-M18-M20 -> 28748.771 | N21: =M21/M19 -> 0.14137897 | O21: =M21/25 -> 1149.9509
A22: Tax Rate | B22: 0.23 | N22: =N18+N20+N21 -> 1
A23: ITC Rate | B23: 0.3
A24: ITC Amount | B24: =B17*B23 -> 16356.645 | L24: Utilization | M24: =M19/M17 -> 0.74565199
A25: ITC year | B25: 1
H26: Effective PPA | I26: 0.1225
A27: Year | B27: Effective Output | C27: Escalation Factor | D27: Admin Cost | E27: Insurance Cost | F27: Maintenance Cost | G27: OPEX | H27: Capital Cost Allowance | I27: Revenue | J27: Debt Principal | K27: Debt Interest | L27: ITC Credit | M27: Pre Tax Operating Cashflow | N27: Taxable Income Before Carry Forward Loss | O27: Carry Forward Losses | P27: Taxable Income After Carry Forward Loss | Q27: Tax | R27: After Tax Income | S27: Principal Repayent | T27: Cashflow To Equity | U27: Cumulative Equity
A28: 0 | B28: =POWER(1-$B$8,A28)*$B$3 -> 65000 | C28: =POWER(1+$B$9,A28) -> 1 | D28: =$B$7*C28*$B$10 -> 817.83227 | E28: =$B$7*$C28*$B$11 -> 817.83227 | F28: =$B$7*$C28*$B$12 -> 817.83227 | G28: =SUM(D28:F28) -> 2453.4968 | H28: =IF(A28=0,$B$17*$B$14*$B$13,H27*$B$13) -> 8178.3227 | I28: =B28*$I$26 -> 7962.5 | J28: =MAX(IF(A28>=$B$20,J27-$B$21,$B$17),0) -> 54522.151 | K28: =IF(A28>=$B$20,J28*$B$18,0) -> 0 | L28: =IF(A28=$B$25,$B$24,0) -> 0 | M28: =I28-G28-K28+L28 -> 5509.0032 | N28: =M28-H28 -> -2669.3195 | O28: =IF(N28<0,N28,0) -> -2669.3195 | P28: =IF(N28>0,N28+O27,0) -> 0 | Q28: =$B$22*P28 -> 0 | R28: =M28-Q28 -> 5509.0032 | S28: =IFERROR(__xludf.DUMMYFUNCTION("IF(ISBETWEEN(A28,$B$20,$B$20+$B$19-1),$B$21,0)"),0.0) -> 0 | T28: =R28-S28 -> 5509.0032 | U28: =T28 -> 5509.0032
A29: 1 | B29: =POWER(1-$B$8,A29)*$B$3 -> 64675 | C29: =POWER(1+$B$9,A29) -> 1.03 | D29: =$B$7*C29*$B$10 -> 842.36723 | E29: =$B$7*$C29*$B$11 -> 842.36723 | F29: =$B$7*$C29*$B$12 -> 842.36723 | G29: =SUM(D29:F29) -> 2527.1017 | H29: =IF(A29=0,$B$17*$B$14*$B$13,H28*$B$13) -> 2453.4968 | I29: =B29*$I$26 -> 7922.6875 | J29: =MAX(IF(A29>=$B$20,J28-$B$21,$B$17),0) -> 54522.151 | K29: =IF(A29>=$B$20,J29*$B$18,0) -> 0 | L29: =IF(A29=$B$25,$B$24,0) -> 16356.645 | M29: =I29-G29-K29+L29 -> 21752.231 | N29: =M29-H29 -> 19298.734 | O29: =IF(N29<0,N29,0) -> 0 | P29: =IF(N29>0,N29+O28,0) -> 16629.415 | Q29: =$B$22*P29 -> 3824.7654 | R29: =M29-Q29 -> 17927.466 | S29: =IFERROR(__xludf.DUMMYFUNCTION("IF(ISBETWEEN(A29,$B$20,$B$20+$B$19-1),$B$21,0)"),0.0) -> 0 | T29: =R29-S29 -> 17927.466 | U29: =T29+U28 -> 23436.469
A30: 2 | B30: =POWER(1-$B$8,A30)*$B$3 -> 64351.625 | C30: =POWER(1+$B$9,A30) -> 1.0609 | D30: =$B$7*C30*$B$10 -> 867.63825 | E30: =$B$7*$C30*$B$11 -> 867.63825 | F30: =$B$7*$C30*$B$12 -> 867.63825 | G30: =SUM(D30:F30) -> 2602.9148 | H30: =IF(A30=0,$B$17*$B$14*$B$13,H29*$B$13) -> 736.04904 | I30: =B30*$I$26 -> 7883.0741 | J30: =MAX(IF(A30>=$B$20,J29-$B$21,$B$17),0) -> 54522.151 | K30: =IF(A30>=$B$20,J30*$B$18,0) -> 0 | L30: =IF(A30=$B$25,$B$24,0) -> 0 | M30: =I30-G30-K30+L30 -> 5280.1593 | N30: =M30-H30 -> 4544.1103 | O30: =IF(N30<0,N30,0) -> 0 | P30: =IF(N30>0,N30+O29,0) -> 4544.1103 | Q30: =$B$22*P30 -> 1045.1454 | R30: =M30-Q30 -> 4235.0139 | S30: =IFERROR(__xludf.DUMMYFUNCTION("IF(ISBETWEEN(A30,$B$20,$B$20+$B$19-1),$B$21,0)"),0.0) -> 0 | T30: =R30-S30 -> 4235.0139 | U30: =T30+U29 -> 27671.483
A31: 3 | B31: =POWER(1-$B$8,A31)*$B$3 -> 64029.867 | C31: =POWER(1+$B$9,A31) -> 1.092727 | D31: =$B$7*C31*$B$10 -> 893.6674 | E31: =$B$7*$C31*$B$11 -> 893.6674 | F31: =$B$7*$C31*$B$12 -> 893.6674 | G31: =SUM(D31:F31) -> 2681.0022 | H31: =IF(A31=0,$B$17*$B$14*$B$13,H30*$B$13) -> 220.81471 | I31: =B31*$I$26 -> 7843.6587 | J31: =MAX(IF(A31>=$B$20,J30-$B$21,$B$17),0) -> 49069.936 | K31: =IF(A31>=$B$20,J31*$B$18,0) -> 1962.7974 | L31: =IF(A31=$B$25,$B$24,0) -> 0 | M31: =I31-G31-K31+L31 -> 3199.8591 | N31: =M31-H31 -> 2979.0443 | O31: =IF(N31<0,N31,0) -> 0 | P31: =IF(N31>0,N31+O30,0) -> 2979.0443 | Q31: =$B$22*P31 -> 685.1802 | R31: =M31-Q31 -> 2514.6789 | S31: =IFERROR(__xludf.DUMMYFUNCTION("IF(ISBETWEEN(A31,$B$20,$B$20+$B$19-1),$B$21,0)"),5452.215109178511) -> 5452.2151 | T31: =R31-S31 -> -2937.5363 | U31: =T31+U30 -> 24733.947
A32: 4 | B32: =POWER(1-$B$8,A32)*$B$3 -> 63709.718 | C32: =POWER(1+$B$9,A32) -> 1.1255088 | D32: =$B$7*C32*$B$10 -> 920.47742 | E32: =$B$7*$C32*$B$11 -> 920.47742 | F32: =$B$7*$C32*$B$12 -> 920.47742 | G32: =SUM(D32:F32) -> 2761.4323 | H32: =IF(A32=0,$B$17*$B$14*$B$13,H31*$B$13) -> 66.244414 | I32: =B32*$I$26 -> 7804.4404 | J32: =MAX(IF(A32>=$B$20,J31-$B$21,$B$17),0) -> 43617.721 | K32: =IF(A32>=$B$20,J32*$B$18,0) -> 1744.7088 | L32: =IF(A32=$B$25,$B$24,0) -> 0 | M32: =I32-G32-K32+L32 -> 3298.2993 | N32: =M32-H32 -> 3232.0549 | O32: =IF(N32<0,N32,0) -> 0 | P32: =IF(N32>0,N32+O31,0) -> 3232.0549 | Q32: =$B$22*P32 -> 743.37262 | R32: =M32-Q32 -> 2554.9267 | S32: =IFERROR(__xludf.DUMMYFUNCTION("IF(ISBETWEEN(A32,$B$20,$B$20+$B$19-1),$B$21,0)"),5452.215109178511) -> 5452.2151 | T32: =R32-S32 -> -2897.2884 | U32: =T32+U31 -> 21836.658
A33: 5 | B33: =POWER(1-$B$8,A33)*$B$3 -> 63391.169 | C33: =POWER(1+$B$9,A33) -> 1.1592741 | D33: =$B$7*C33*$B$10 -> 948.09174 | E33: =$B$7*$C33*$B$11 -> 948.09174 | F33: =$B$7*$C33*$B$12 -> 948.09174 | G33: =SUM(D33:F33) -> 2844.2752 | H33: =IF(A33=0,$B$17*$B$14*$B$13,H32*$B$13) -> 19.873324 | I33: =B33*$I$26 -> 7765.4182 | J33: =MAX(IF(A33>=$B$20,J32-$B$21,$B$17),0) -> 38165.506 | K33: =IF(A33>=$B$20,J33*$B$18,0) -> 1526.6202 | L33: =IF(A33=$B$25,$B$24,0) -> 0 | M33: =I33-G33-K33+L33 -> 3394.5227 | N33: =M33-H33 -> 3374.6494 | O33: =IF(N33<0,N33,0) -> 0 | P33: =IF(N33>0,N33+O32,0) -> 3374.6494 | Q33: =$B$22*P33 -> 776.16936 | R33: =M33-Q33 -> 2618.3534 | S33: =IFERROR(__xludf.DUMMYFUNCTION("IF(ISBETWEEN(A33,$B$20,$B$20+$B$19-1),$B$21,0)"),5452.215109178511) -> 5452.2151 | T33: =R33-S33 -> -2833.8617 | U33: =T33+U32 -> 19002.796
A34: 6 | B34: =POWER(1-$B$8,A34)*$B$3 -> 63074.213 | C34: =POWER(1+$B$9,A34) -> 1.1940523 | D34: =$B$7*C34*$B$10 -> 976.5345 | E34: =$B$7*$C34*$B$11 -> 976.5345 | F34: =$B$7*$C34*$B$12 -> 976.5345 | G34: =SUM(D34:F34) -> 2929.6035 | H34: =IF(A34=0,$B$17*$B$14*$B$13,H33*$B$13) -> 5.9619972 | I34: =B34*$I$26 -> 7726.5911 | J34: =MAX(IF(A34>=$B$20,J33-$B$21,$B$17),0) -> 32713.291 | K34: =IF(A34>=$B$20,J34*$B$18,0) -> 1308.5316 | L34: =IF(A34=$B$25,$B$24,0) -> 0 | M34: =I34-G34-K34+L34 -> 3488.456 | N34: =M34-H34 -> 3482.494 | O34: =IF(N34<0,N34,0) -> 0 | P34: =IF(N34>0,N34+O33,0) -> 3482.494 | Q34: =$B$22*P34 -> 800.97362 | R34: =M34-Q34 -> 2687.4824 | S34: =IFERROR(__xludf.DUMMYFUNCTION("IF(ISBETWEEN(A34,$B$20,$B$20+$B$19-1),$B$21,0)"),5452.215109178511) -> 5452.2151 | T34: =R34-S34 -> -2764.7327 | U34: =T34+U33 -> 16238.064
A35: 7 | B35: =POWER(1-$B$8,A35)*$B$3 -> 62758.842 | C35: =POWER(1+$B$9,A35) -> 1.2298739 | D35: =$B$7*C35*$B$10 -> 1005.8305 | E35: =$B$7*$C35*$B$11 -> 1005.8305 | F35: =$B$7*$C35*$B$12 -> 1005.8305 | G35: =SUM(D35:F35) -> 3017.4916 | H35: =IF(A35=0,$B$17*$B$14*$B$13,H34*$B$13) -> 1.7885992 | I35: =B35*$I$26 -> 7687.9582 | J35: =MAX(IF(A35>=$B$20,J34-$B$21,$B$17),0) -> 27261.076 | K35: =IF(A35>=$B$20,J35*$B$18,0) -> 1090.443 | L35: =IF(A35=$B$25,$B$24,0) -> 0 | M35: =I35-G35-K35+L35 -> 3580.0235 | N35: =M35-H35 -> 3578.2349 | O35: =IF(N35<0,N35,0) -> 0 | P35: =IF(N35>0,N35+O34,0) -> 3578.2349 | Q35: =$B$22*P35 -> 822.99404 | R35: =M35-Q35 -> 2757.0295 | S35: =IFERROR(__xludf.DUMMYFUNCTION("IF(ISBETWEEN(A35,$B$20,$B$20+$B$19-1),$B$21,0)"),5452.215109178511) -> 5452.2151 | T35: =R35-S35 -> -2695.1856 | U35: =T35+U34 -> 13542.878
A36: 8 | B36: =POWER(1-$B$8,A36)*$B$3 -> 62445.048 | C36: =POWER(1+$B$9,A36) -> 1.2667701 | D36: =$B$7*C36*$B$10 -> 1036.0054 | E36: =$B$7*$C36*$B$11 -> 1036.0054 | F36: =$B$7*$C36*$B$12 -> 1036.0054 | G36: =SUM(D36:F36) -> 3108.0163 | H36: =IF(A36=0,$B$17*$B$14*$B$13,H35*$B$13) -> 0.53657975 | I36: =B36*$I$26 -> 7649.5184 | J36: =MAX(IF(A36>=$B$20,J35-$B$21,$B$17),0) -> 21808.86 | K36: =IF(A36>=$B$20,J36*$B$18,0) -> 872.35442 | L36: =IF(A36=$B$25,$B$24,0) -> 0 | M36: =I36-G36-K36+L36 -> 3669.1476 | N36: =M36-H36 -> 3668.611 | O36: =IF(N36<0,N36,0) -> 0 | P36: =IF(N36>0,N36+O35,0) -> 3668.611 | Q36: =$B$22*P36 -> 843.78054 | R36: =M36-Q36 -> 2825.3671 | S36: =IFERROR(__xludf.DUMMYFUNCTION("IF(ISBETWEEN(A36,$B$20,$B$20+$B$19-1),$B$21,0)"),5452.215109178511) -> 5452.2151 | T36: =R36-S36 -> -2626.848 | U36: =T36+U35 -> 10916.03
A37: 9 | B37: =POWER(1-$B$8,A37)*$B$3 -> 62132.823 | C37: =POWER(1+$B$9,A37) -> 1.3047732 | D37: =$B$7*C37*$B$10 -> 1067.0856 | E37: =$B$7*$C37*$B$11 -> 1067.0856 | F37: =$B$7*$C37*$B$12 -> 1067.0856 | G37: =SUM(D37:F37) -> 3201.2568 | H37: =IF(A37=0,$B$17*$B$14*$B$13,H36*$B$13) -> 0.16097392 | I37: =B37*$I$26 -> 7611.2708 | J37: =MAX(IF(A37>=$B$20,J36-$B$21,$B$17),0) -> 16356.645 | K37: =IF(A37>=$B$20,J37*$B$18,0) -> 654.26581 | L37: =IF(A37=$B$25,$B$24,0) -> 0 | M37: =I37-G37-K37+L37 -> 3755.7481 | N37: =M37-H37 -> 3755.5872 | O37: =IF(N37<0,N37,0) -> 0 | P37: =IF(N37>0,N37+O36,0) -> 3755.5872 | Q37: =$B$22*P37 -> 863.78504 | R37: =M37-Q37 -> 2891.9631 | S37: =IFERROR(__xludf.DUMMYFUNCTION("IF(ISBETWEEN(A37,$B$20,$B$20+$B$19-1),$B$21,0)"),5452.215109178511) -> 5452.2151 | T37: =R37-S37 -> -2560.252 | U37: =T37+U36 -> 8355.778
A38: 10 | B38: =POWER(1-$B$8,A38)*$B$3 -> 61822.158 | C38: =POWER(1+$B$9,A38) -> 1.3439164 | D38: =$B$7*C38*$B$10 -> 1099.0982 | E38: =$B$7*$C38*$B$11 -> 1099.0982 | F38: =$B$7*$C38*$B$12 -> 1099.0982 | G38: =SUM(D38:F38) -> 3297.2945 | H38: =IF(A38=0,$B$17*$B$14*$B$13,H37*$B$13) -> 0.048292177 | I38: =B38*$I$26 -> 7573.2144 | J38: =MAX(IF(A38>=$B$20,J37-$B$21,$B$17),0) -> 10904.43 | K38: =IF(A38>=$B$20,J38*$B$18,0) -> 436.17721 | L38: =IF(A38=$B$25,$B$24,0) -> 0 | M38: =I38-G38-K38+L38 -> 3839.7427 | N38: =M38-H38 -> 3839.6944 | O38: =IF(N38<0,N38,0) -> 0 | P38: =IF(N38>0,N38+O37,0) -> 3839.6944 | Q38: =$B$22*P38 -> 883.12971 | R38: =M38-Q38 -> 2956.613 | S38: =IFERROR(__xludf.DUMMYFUNCTION("IF(ISBETWEEN(A38,$B$20,$B$20+$B$19-1),$B$21,0)"),5452.215109178511) -> 5452.2151 | T38: =R38-S38 -> -2495.6021 | U38: =T38+U37 -> 5860.1759
A39: 11 | B39: =POWER(1-$B$8,A39)*$B$3 -> 61513.048 | C39: =POWER(1+$B$9,A39) -> 1.3842339 | D39: =$B$7*C39*$B$10 -> 1132.0711 | E39: =$B$7*$C39*$B$11 -> 1132.0711 | F39: =$B$7*$C39*$B$12 -> 1132.0711 | G39: =SUM(D39:F39) -> 3396.2134 | H39: =IF(A39=0,$B$17*$B$14*$B$13,H38*$B$13) -> 0.014487653 | I39: =B39*$I$26 -> 7535.3483 | J39: =MAX(IF(A39>=$B$20,J38-$B$21,$B$17),0) -> 5452.2151 | K39: =IF(A39>=$B$20,J39*$B$18,0) -> 218.0886 | L39: =IF(A39=$B$25,$B$24,0) -> 0 | M39: =I39-G39-K39+L39 -> 3921.0464 | N39: =M39-H39 -> 3921.0319 | O39: =IF(N39<0,N39,0) -> 0 | P39: =IF(N39>0,N39+O38,0) -> 3921.0319 | Q39: =$B$22*P39 -> 901.83733 | R39: =M39-Q39 -> 3019.209 | S39: =IFERROR(__xludf.DUMMYFUNCTION("IF(ISBETWEEN(A39,$B$20,$B$20+$B$19-1),$B$21,0)"),5452.215109178511) -> 5452.2151 | T39: =R39-S39 -> -2433.0061 | U39: =T39+U38 -> 3427.1698
A40: 12 | B40: =POWER(1-$B$8,A40)*$B$3 -> 61205.482 | C40: =POWER(1+$B$9,A40) -> 1.4257609 | D40: =$B$7*C40*$B$10 -> 1166.0333 | E40: =$B$7*$C40*$B$11 -> 1166.0333 | F40: =$B$7*$C40*$B$12 -> 1166.0333 | G40: =SUM(D40:F40) -> 3498.0998 | H40: =IF(A40=0,$B$17*$B$14*$B$13,H39*$B$13) -> 0.004346296 | I40: =B40*$I$26 -> 7497.6716 | J40: =MAX(IF(A40>=$B$20,J39-$B$21,$B$17),0) -> 0 | K40: =IF(A40>=$B$20,J40*$B$18,0) -> 0 | L40: =IF(A40=$B$25,$B$24,0) -> 0 | M40: =I40-G40-K40+L40 -> 3999.5718 | N40: =M40-H40 -> 3999.5675 | O40: =IF(N40<0,N40,0) -> 0 | P40: =IF(N40>0,N40+O39,0) -> 3999.5675 | Q40: =$B$22*P40 -> 919.90052 | R40: =M40-Q40 -> 3079.6713 | S40: =IFERROR(__xludf.DUMMYFUNCTION("IF(ISBETWEEN(A40,$B$20,$B$20+$B$19-1),$B$21,0)"),5452.215109178511) -> 5452.2151 | T40: =R40-S40 -> -2372.5438 | U40: =T40+U39 -> 1054.626
A41: 13 | B41: =POWER(1-$B$8,A41)*$B$3 -> 60899.455 | C41: =POWER(1+$B$9,A41) -> 1.4685337 | D41: =$B$7*C41*$B$10 -> 1201.0143 | E41: =$B$7*$C41*$B$11 -> 1201.0143 | F41: =$B$7*$C41*$B$12 -> 1201.0143 | G41: =SUM(D41:F41) -> 3603.0428 | H41: =IF(A41=0,$B$17*$B$14*$B$13,H40*$B$13) -> 0.0013038888 | I41: =B41*$I$26 -> 7460.1832 | J41: =MAX(IF(A41>=$B$20,J40-$B$21,$B$17),0) -> 0 | K41: =IF(A41>=$B$20,J41*$B$18,0) -> 0 | L41: =IF(A41=$B$25,$B$24,0) -> 0 | M41: =I41-G41-K41+L41 -> 3857.1405 | N41: =M41-H41 -> 3857.1392 | O41: =IF(N41<0,N41,0) -> 0 | P41: =IF(N41>0,N41+O40,0) -> 3857.1392 | Q41: =$B$22*P41 -> 887.14201 | R41: =M41-Q41 -> 2969.9985 | S41: =IFERROR(__xludf.DUMMYFUNCTION("IF(ISBETWEEN(A41,$B$20,$B$20+$B$19-1),$B$21,0)"),0.0) -> 0 | T41: =R41-S41 -> 2969.9985 | U41: =T41+U40 -> 4024.6245
...

Sheet Billing Rate
A1: Consumption | B1: 0.068
A2: Ratchet Demand | B2: 25

Sheet Rate Codes
A1: Code | B1: Type | C1: Component Type | D1: Price
A2: D300 | B2: Distribution | C2: Service Charge | D2: 9.591923
A3: D300 | B3: Distribution | C3: Facilities Charge | D3: 0.065117
